Workbook

Sheet Dashboard
B2: Time Off | O2: ="Updated "&TEXT(TODAY(),"mmm d")
B3: 2026 · all employees
B5: Team PTO (incl. banked) | I5: =IF(SUM($D$23:$D$42)=0,"No allotment set yet",TEXT(SUM($D$23:$D$42)-SUM($C$23:$C$42),"0.#")&" of "&TEXT(SUM($D$23:$D$42),"0.#")&" days left") | O5: =IF(SUM($D$23:$D$42)=0,0,SUM($C$23:$C$42)/SUM($D$23:$D$42))
B6: =REPT("█",ROUND(MIN(1,O5)*70,0))&REPT("░",70-ROUND(MIN(1,O5)*70,0))
B8: Holidays | I8: =IF(SUM(Q23:Q42)=0,"No allotment set yet",TEXT(SUM(Q23:Q42)-SUM(R23:R42),"0.#")&" of "&TEXT(SUM(Q23:Q42),"0.#")&" days left") | O8: =IF(SUM(Q23:Q42)=0,0,SUM(R23:R42)/SUM(Q23:Q42))
B9: =REPT("█",ROUND(MIN(1,O8)*70,0))&REPT("░",70-ROUND(MIN(1,O8)*70,0))
B12: This year
B13: PTO | C13: =SUM(J23:J42) | E13: Banked PTO | F13: =SUM(K23:K42) | I13: Bereavement | K13: =SUM(L23:L42)
B14: Jury duty | C14: =SUM(M23:M42) | E14: Training | F14: =SUM(N23:N42) | I14: Out this month | K14: =SUM(H23:H42)
B17: Highest PTO usage | I17: Top 3 by % of allotment
B18: =IF(INDEX($F$23:$F$42,MATCH(LARGE($P$23:$P$42,1),$P$23:$P$42,0))>0,INDEX($B$23:$B$42,MATCH(LARGE($P$23:$P$42,1),$P$23:$P$42,0)),"—") | E18: =IF(B18="—","",INDEX($O$23:$O$42,MATCH(LARGE($P$23:$P$42,1),$P$23:$P$42,0))) | O18: =IF(B18="—","",INDEX($F$23:$F$42,MATCH(LARGE($P$23:$P$42,1),$P$23:$P$42,0)))
B19: =IF(INDEX($F$23:$F$42,MATCH(LARGE($P$23:$P$42,2),$P$23:$P$42,0))>0,INDEX($B$23:$B$42,MATCH(LARGE($P$23:$P$42,2),$P$23:$P$42,0)),"—") | E19: =IF(B19="—","",INDEX($O$23:$O$42,MATCH(LARGE($P$23:$P$42,2),$P$23:$P$42,0))) | O19: =IF(B19="—","",INDEX($F$23:$F$42,MATCH(LARGE($P$23:$P$42,2),$P$23:$P$42,0)))
B20: =IF(INDEX($F$23:$F$42,MATCH(LARGE($P$23:$P$42,3),$P$23:$P$42,0))>0,INDEX($B$23:$B$42,MATCH(LARGE($P$23:$P$42,3),$P$23:$P$42,0)),"—") | E20: =IF(B20="—","",INDEX($O$23:$O$42,MATCH(LARGE($P$23:$P$42,3),$P$23:$P$42,0))) | O20: =IF(B20="—","",INDEX($F$23:$F$42,MATCH(LARGE($P$23:$P$42,3),$P$23:$P$42,0)))
B22: Employee | C22: PTO used | D22: Allotted | F22: % used | G22: Left | H22: This month | I22: Holidays | J22: PTO | K22: Banked | L22: Bereav. | M22: Jury | N22: Training | O22: Status | P22: Sort key | Q22: Hol. allot. | R22: Hol. used
B23: ='EMPLOYEE1'!A2 | C23: ='EMPLOYEE1'!AI23+'EMPLOYEE1'!AJ23 | D23: =N('EMPLOYEE1'!D5)+N('EMPLOYEE1'!D6) | E23: =REPT("█",ROUND(MIN(1,F23)*20,0))&REPT("░",20-ROUND(MIN(1,F23)*20,0)) | F23: =IF(D23=0,0,C23/D23) | G23: =IF(D23=0,"—",D23-C23) | H23: =SUM(INDEX('EMPLOYEE1'!$AI$11:$AM$22,MONTH(TODAY()),0)) | I23: =R23&" of "&Q23 | J23: ='EMPLOYEE1'!AI23 | K23: ='EMPLOYEE1'!AJ23 | L23: ='EMPLOYEE1'!AK23 | M23: ='EMPLOYEE1'!AL23 | N23: ='EMPLOYEE1'!AM23 | O23: =IF(D23=0,"Set allotment",IF(F23>=1,"Over",IF(F23>=0.8,"Running low","On track"))) | P23: =F23+(100-ROW())/100000 | Q23: =N('EMPLOYEE1'!D7) | R23: ='EMPLOYEE1'!AH23
B24: ='EMPLOYEE2'!A2 | C24: ='EMPLOYEE2'!AI23+'EMPLOYEE2'!AJ23 | D24: =N('EMPLOYEE2'!D5)+N('EMPLOYEE2'!D6) | E24: =REPT("█",ROUND(MIN(1,F24)*20,0))&REPT("░",20-ROUND(MIN(1,F24)*20,0)) | F24: =IF(D24=0,0,C24/D24) | G24: =IF(D24=0,"—",D24-C24) | H24: =SUM(INDEX('EMPLOYEE2'!$AI$11:$AM$22,MONTH(TODAY()),0)) | I24: =R24&" of "&Q24 | J24: ='EMPLOYEE2'!AI23 | K24: ='EMPLOYEE2'!AJ23 | L24: ='EMPLOYEE2'!AK23 | M24: ='EMPLOYEE2'!AL23 | N24: ='EMPLOYEE2'!AM23 | O24: =IF(D24=0,"Set allotment",IF(F24>=1,"Over",IF(F24>=0.8,"Running low","On track"))) | P24: =F24+(100-ROW())/100000 | Q24: =N('EMPLOYEE2'!D7) | R24: ='EMPLOYEE2'!AH23
B25: ='EMPLOYEE3'!A2 | C25: ='EMPLOYEE3'!AI23+'EMPLOYEE3'!AJ23 | D25: =N('EMPLOYEE3'!D5)+N('EMPLOYEE3'!D6) | E25: =REPT("█",ROUND(MIN(1,F25)*20,0))&REPT("░",20-ROUND(MIN(1,F25)*20,0)) | F25: =IF(D25=0,0,C25/D25) | G25: =IF(D25=0,"—",D25-C25) | H25: =SUM(INDEX('EMPLOYEE3'!$AI$11:$AM$22,MONTH(TODAY()),0)) | I25: =R25&" of "&Q25 | J25: ='EMPLOYEE3'!AI23 | K25: ='EMPLOYEE3'!AJ23 | L25: ='EMPLOYEE3'!AK23 | M25: ='EMPLOYEE3'!AL23 | N25: ='EMPLOYEE3'!AM23 | O25: =IF(D25=0,"Set allotment",IF(F25>=1,"Over",IF(F25>=0.8,"Running low","On track"))) | P25: =F25+(100-ROW())/100000 | Q25: =N('EMPLOYEE3'!D7) | R25: ='EMPLOYEE3'!AH23
B26: ='EMPLOYEE4'!A2 | C26: ='EMPLOYEE4'!AI23+'EMPLOYEE4'!AJ23 | D26: =N('EMPLOYEE4'!D5)+N('EMPLOYEE4'!D6) | E26: =REPT("█",ROUND(MIN(1,F26)*20,0))&REPT("░",20-ROUND(MIN(1,F26)*20,0)) | F26: =IF(D26=0,0,C26/D26) | G26: =IF(D26=0,"—",D26-C26) | H26: =SUM(INDEX('EMPLOYEE4'!$AI$11:$AM$22,MONTH(TODAY()),0)) | I26: =R26&" of "&Q26 | J26: ='EMPLOYEE4'!AI23 | K26: ='EMPLOYEE4'!AJ23 | L26: ='EMPLOYEE4'!AK23 | M26: ='EMPLOYEE4'!AL23 | N26: ='EMPLOYEE4'!AM23 | O26: =IF(D26=0,"Set allotment",IF(F26>=1,"Over",IF(F26>=0.8,"Running low","On track"))) | P26: =F26+(100-ROW())/100000 | Q26: =N('EMPLOYEE4'!D7) | R26: ='EMPLOYEE4'!AH23
B27: ='EMPLOYEE5'!A2 | C27: ='EMPLOYEE5'!AI23+'EMPLOYEE5'!AJ23 | D27: =N('EMPLOYEE5'!D5)+N('EMPLOYEE5'!D6) | E27: =REPT("█",ROUND(MIN(1,F27)*20,0))&REPT("░",20-ROUND(MIN(1,F27)*20,0)) | F27: =IF(D27=0,0,C27/D27) | G27: =IF(D27=0,"—",D27-C27) | H27: =SUM(INDEX('EMPLOYEE5'!$AI$11:$AM$22,MONTH(TODAY()),0)) | I27: =R27&" of "&Q27 | J27: ='EMPLOYEE5'!AI23 | K27: ='EMPLOYEE5'!AJ23 | L27: ='EMPLOYEE5'!AK23 | M27: ='EMPLOYEE5'!AL23 | N27: ='EMPLOYEE5'!AM23 | O27: =IF(D27=0,"Set allotment",IF(F27>=1,"Over",IF(F27>=0.8,"Running low","On track"))) | P27: =F27+(100-ROW())/100000 | Q27: =N('EMPLOYEE5'!D7) | R27: ='EMPLOYEE5'!AH23
B28: ='EMPLOYEE6'!A2 | C28: ='EMPLOYEE6'!AI23+'EMPLOYEE6'!AJ23 | D28: =N('EMPLOYEE6'!D5)+N('EMPLOYEE6'!D6) | E28: =REPT("█",ROUND(MIN(1,F28)*20,0))&REPT("░",20-ROUND(MIN(1,F28)*20,0)) | F28: =IF(D28=0,0,C28/D28) | G28: =IF(D28=0,"—",D28-C28) | H28: =SUM(INDEX('EMPLOYEE6'!$AI$11:$AM$22,MONTH(TODAY()),0)) | I28: =R28&" of "&Q28 | J28: ='EMPLOYEE6'!AI23 | K28: ='EMPLOYEE6'!AJ23 | L28: ='EMPLOYEE6'!AK23 | M28: ='EMPLOYEE6'!AL23 | N28: ='EMPLOYEE6'!AM23 | O28: =IF(D28=0,"Set allotment",IF(F28>=1,"Over",IF(F28>=0.8,"Running low","On track"))) | P28: =F28+(100-ROW())/100000 | Q28: =N('EMPLOYEE6'!D7) | R28: ='EMPLOYEE6'!AH23
B29: ='EMPLOYEE7'!A2 | C29: ='EMPLOYEE7'!AI23+'EMPLOYEE7'!AJ23 | D29: =N('EMPLOYEE7'!D5)+N('EMPLOYEE7'!D6) | E29: =REPT("█",ROUND(MIN(1,F29)*20,0))&REPT("░",20-ROUND(MIN(1,F29)*20,0)) | F29: =IF(D29=0,0,C29/D29) | G29: =IF(D29=0,"—",D29-C29) | H29: =SUM(INDEX('EMPLOYEE7'!$AI$11:$AM$22,MONTH(TODAY()),0)) | I29: =R29&" of "&Q29 | J29: ='EMPLOYEE7'!AI23 | K29: ='EMPLOYEE7'!AJ23 | L29: ='EMPLOYEE7'!AK23 | M29: ='EMPLOYEE7'!AL23 | N29: ='EMPLOYEE7'!AM23 | O29: =IF(D29=0,"Set allotment",IF(F29>=1,"Over",IF(F29>=0.8,"Running low","On track"))) | P29: =F29+(100-ROW())/100000 | Q29: =N('EMPLOYEE7'!D7) | R29: ='EMPLOYEE7'!AH23
B30: ='EMPLOYEE8'!A2 | C30: ='EMPLOYEE8'!AI23+'EMPLOYEE8'!AJ23 | D30: =N('EMPLOYEE8'!D5)+N('EMPLOYEE8'!D6) | E30: =REPT("█",ROUND(MIN(1,F30)*20,0))&REPT("░",20-ROUND(MIN(1,F30)*20,0)) | F30: =IF(D30=0,0,C30/D30) | G30: =IF(D30=0,"—",D30-C30) | H30: =SUM(INDEX('EMPLOYEE8'!$AI$11:$AM$22,MONTH(TODAY()),0)) | I30: =R30&" of "&Q30 | J30: ='EMPLOYEE8'!AI23 | K30: ='EMPLOYEE8'!AJ23 | L30: ='EMPLOYEE8'!AK23 | M30: ='EMPLOYEE8'!AL23 | N30: ='EMPLOYEE8'!AM23 | O30: =IF(D30=0,"Set allotment",IF(F30>=1,"Over",IF(F30>=0.8,"Running low","On track"))) | P30: =F30+(100-ROW())/100000 | Q30: =N('EMPLOYEE8'!D7) | R30: ='EMPLOYEE8'!AH23
B31: ='EMPLOYEE9'!A2 | C31: ='EMPLOYEE9'!AI23+'EMPLOYEE9'!AJ23 | D31: =N('EMPLOYEE9'!D5)+N('EMPLOYEE9'!D6) | E31: =REPT("█",ROUND(MIN(1,F31)*20,0))&REPT("░",20-ROUND(MIN(1,F31)*20,0)) | F31: =IF(D31=0,0,C31/D31) | G31: =IF(D31=0,"—",D31-C31) | H31: =SUM(INDEX('EMPLOYEE9'!$AI$11:$AM$22,MONTH(TODAY()),0)) | I31: =R31&" of "&Q31 | J31: ='EMPLOYEE9'!AI23 | K31: ='EMPLOYEE9'!AJ23 | L31: ='EMPLOYEE9'!AK23 | M31: ='EMPLOYEE9'!AL23 | N31: ='EMPLOYEE9'!AM23 | O31: =IF(D31=0,"Set allotment",IF(F31>=1,"Over",IF(F31>=0.8,"Running low","On track"))) | P31: =F31+(100-ROW())/100000 | Q31: =N('EMPLOYEE9'!D7) | R31: ='EMPLOYEE9'!AH23
B32: ='EMPLOYEE10'!A2 | C32: ='EMPLOYEE10'!AI23+'EMPLOYEE10'!AJ23 | D32: =N('EMPLOYEE10'!D5)+N('EMPLOYEE10'!D6) | E32: =REPT("█",ROUND(MIN(1,F32)*20,0))&REPT("░",20-ROUND(MIN(1,F32)*20,0)) | F32: =IF(D32=0,0,C32/D32) | G32: =IF(D32=0,"—",D32-C32) | H32: =SUM(INDEX('EMPLOYEE10'!$AI$11:$AM$22,MONTH(TODAY()),0)) | I32: =R32&" of "&Q32 | J32: ='EMPLOYEE10'!AI23 | K32: ='EMPLOYEE10'!AJ23 | L32: ='EMPLOYEE10'!AK23 | M32: ='EMPLOYEE10'!AL23 | N32: ='EMPLOYEE10'!AM23 | O32: =IF(D32=0,"Set allotment",IF(F32>=1,"Over",IF(F32>=0.8,"Running low","On track"))) | P32: =F32+(100-ROW())/100000 | Q32: =N('EMPLOYEE10'!D7) | R32: ='EMPLOYEE10'!AH23
B33: ='EMPLOYEE11'!A2 | C33: ='EMPLOYEE11'!AI23+'EMPLOYEE11'!AJ23 | D33: =N('EMPLOYEE11'!D5)+N('EMPLOYEE11'!D6) | E33: =REPT("█",ROUND(MIN(1,F33)*20,0))&REPT("░",20-ROUND(MIN(1,F33)*20,0)) | F33: =IF(D33=0,0,C33/D33) | G33: =IF(D33=0,"—",D33-C33) | H33: =SUM(INDEX('EMPLOYEE11'!$AI$11:$AM$22,MONTH(TODAY()),0)) | I33: =R33&" of "&Q33 | J33: ='EMPLOYEE11'!AI23 | K33: ='EMPLOYEE11'!AJ23 | L33: ='EMPLOYEE11'!AK23 | M33: ='EMPLOYEE11'!AL23 | N33: ='EMPLOYEE11'!AM23 | O33: =IF(D33=0,"Set allotment",IF(F33>=1,"Over",IF(F33>=0.8,"Running low","On track"))) | P33: =F33+(100-ROW())/100000 | Q33: =N('EMPLOYEE11'!D7) | R33: ='EMPLOYEE11'!AH23
B34: ='EMPLOYEE12'!A2 | C34: ='EMPLOYEE12'!AI23+'EMPLOYEE12'!AJ23 | D34: =N('EMPLOYEE12'!D5)+N('EMPLOYEE12'!D6) | E34: =REPT("█",ROUND(MIN(1,F34)*20,0))&REPT("░",20-ROUND(MIN(1,F34)*20,0)) | F34: =IF(D34=0,0,C34/D34) | G34: =IF(D34=0,"—",D34-C34) | H34: =SUM(INDEX('EMPLOYEE12'!$AI$11:$AM$22,MONTH(TODAY()),0)) | I34: =R34&" of "&Q34 | J34: ='EMPLOYEE12'!AI23 | K34: ='EMPLOYEE12'!AJ23 | L34: ='EMPLOYEE12'!AK23 | M34: ='EMPLOYEE12'!AL23 | N34: ='EMPLOYEE12'!AM23 | O34: =IF(D34=0,"Set allotment",IF(F34>=1,"Over",IF(F34>=0.8,"Running low","On track"))) | P34: =F34+(100-ROW())/100000 | Q34: =N('EMPLOYEE12'!D7) | R34: ='EMPLOYEE12'!AH23
B35: ='EMPLOYEE13'!A2 | C35: ='EMPLOYEE13'!AI23+'EMPLOYEE13'!AJ23 | D35: =N('EMPLOYEE13'!D5)+N('EMPLOYEE13'!D6) | E35: =REPT("█",ROUND(MIN(1,F35)*20,0))&REPT("░",20-ROUND(MIN(1,F35)*20,0)) | F35: =IF(D35=0,0,C35/D35) | G35: =IF(D35=0,"—",D35-C35) | H35: =SUM(INDEX('EMPLOYEE13'!$AI$11:$AM$22,MONTH(TODAY()),0)) | I35: =R35&" of "&Q35 | J35: ='EMPLOYEE13'!AI23 | K35: ='EMPLOYEE13'!AJ23 | L35: ='EMPLOYEE13'!AK23 | M35: ='EMPLOYEE13'!AL23 | N35: ='EMPLOYEE13'!AM23 | O35: =IF(D35=0,"Set allotment",IF(F35>=1,"Over",IF(F35>=0.8,"Running low","On track"))) | P35: =F35+(100-ROW())/100000 | Q35: =N('EMPLOYEE13'!D7) | R35: ='EMPLOYEE13'!AH23
B36: ='EMPLOYEE14'!A2 | C36: ='EMPLOYEE14'!AI23+'EMPLOYEE14'!AJ23 | D36: =N('EMPLOYEE14'!D5)+N('EMPLOYEE14'!D6) | E36: =REPT("█",ROUND(MIN(1,F36)*20,0))&REPT("░",20-ROUND(MIN(1,F36)*20,0)) | F36: =IF(D36=0,0,C36/D36) | G36: =IF(D36=0,"—",D36-C36) | H36: =SUM(INDEX('EMPLOYEE14'!$AI$11:$AM$22,MONTH(TODAY()),0)) | I36: =R36&" of "&Q36 | J36: ='EMPLOYEE14'!AI23 | K36: ='EMPLOYEE14'!AJ23 | L36: ='EMPLOYEE14'!AK23 | M36: ='EMPLOYEE14'!AL23 | N36: ='EMPLOYEE14'!AM23 | O36: =IF(D36=0,"Set allotment",IF(F36>=1,"Over",IF(F36>=0.8,"Running low","On track"))) | P36: =F36+(100-ROW())/100000 | Q36: =N('EMPLOYEE14'!D7) | R36: ='EMPLOYEE14'!AH23
B37: ='EMPLOYEE15'!A2 | C37: ='EMPLOYEE15'!AI23+'EMPLOYEE15'!AJ23 | D37: =N('EMPLOYEE15'!D5)+N('EMPLOYEE15'!D6) | E37: =REPT("█",ROUND(MIN(1,F37)*20,0))&REPT("░",20-ROUND(MIN(1,F37)*20,0)) | F37: =IF(D37=0,0,C37/D37) | G37: =IF(D37=0,"—",D37-C37) | H37: =SUM(INDEX('EMPLOYEE15'!$AI$11:$AM$22,MONTH(TODAY()),0)) | I37: =R37&" of "&Q37 | J37: ='EMPLOYEE15'!AI23 | K37: ='EMPLOYEE15'!AJ23 | L37: ='EMPLOYEE15'!AK23 | M37: ='EMPLOYEE15'!AL23 | N37: ='EMPLOYEE15'!AM23 | O37: =IF(D37=0,"Set allotment",IF(F37>=1,"Over",IF(F37>=0.8,"Running low","On track"))) | P37: =F37+(100-ROW())/100000 | Q37: =N('EMPLOYEE15'!D7) | R37: ='EMPLOYEE15'!AH23
B38: ='EMPLOYEE16'!A2 | C38: ='EMPLOYEE16'!AI23+'EMPLOYEE16'!AJ23 | D38: =N('EMPLOYEE16'!D5)+N('EMPLOYEE16'!D6) | E38: =REPT("█",ROUND(MIN(1,F38)*20,0))&REPT("░",20-ROUND(MIN(1,F38)*20,0)) | F38: =IF(D38=0,0,C38/D38) | G38: =IF(D38=0,"—",D38-C38) | H38: =SUM(INDEX('EMPLOYEE16'!$AI$11:$AM$22,MONTH(TODAY()),0)) | I38: =R38&" of "&Q38 | J38: ='EMPLOYEE16'!AI23 | K38: ='EMPLOYEE16'!AJ23 | L38: ='EMPLOYEE16'!AK23 | M38: ='EMPLOYEE16'!AL23 | N38: ='EMPLOYEE16'!AM23 | O38: =IF(D38=0,"Set allotment",IF(F38>=1,"Over",IF(F38>=0.8,"Running low","On track"))) | P38: =F38+(100-ROW())/100000 | Q38: =N('EMPLOYEE16'!D7) | R38: ='EMPLOYEE16'!AH23
B39: ='EMPLOYEE17'!A2 | C39: ='EMPLOYEE17'!AI23+'EMPLOYEE17'!AJ23 | D39: =N('EMPLOYEE17'!D5)+N('EMPLOYEE17'!D6) | E39: =REPT("█",ROUND(MIN(1,F39)*20,0))&REPT("░",20-ROUND(MIN(1,F39)*20,0)) | F39: =IF(D39=0,0,C39/D39) | G39: =IF(D39=0,"—",D39-C39) | H39: =SUM(INDEX('EMPLOYEE17'!$AI$11:$AM$22,MONTH(TODAY()),0)) | I39: =R39&" of "&Q39 | J39: ='EMPLOYEE17'!AI23 | K39: ='EMPLOYEE17'!AJ23 | L39: ='EMPLOYEE17'!AK23 | M39: ='EMPLOYEE17'!AL23 | N39: ='EMPLOYEE17'!AM23 | O39: =IF(D39=0,"Set allotment",IF(F39>=1,"Over",IF(F39>=0.8,"Running low","On track"))) | P39: =F39+(100-ROW())/100000 | Q39: =N('EMPLOYEE17'!D7) | R39: ='EMPLOYEE17'!AH23
B40: ='EMPLOYEE18'!A2 | C40: ='EMPLOYEE18'!AI23+'EMPLOYEE18'!AJ23 | D40: =N('EMPLOYEE18'!D5)+N('EMPLOYEE18'!D6) | E40: =REPT("█",ROUND(MIN(1,F40)*20,0))&REPT("░",20-ROUND(MIN(1,F40)*20,0)) | F40: =IF(D40=0,0,C40/D40) | G40: =IF(D40=0,"—",D40-C40) | H40: =SUM(INDEX('EMPLOYEE18'!$AI$11:$AM$22,MONTH(TODAY()),0)) | I40: =R40&" of "&Q40 | J40: ='EMPLOYEE18'!AI23 | K40: ='EMPLOYEE18'!AJ23 | L40: ='EMPLOYEE18'!AK23 | M40: ='EMPLOYEE18'!AL23 | N40: ='EMPLOYEE18'!AM23 | O40: =IF(D40=0,"Set allotment",IF(F40>=1,"Over",IF(F40>=0.8,"Running low","On track"))) | P40: =F40+(100-ROW())/100000 | Q40: =N('EMPLOYEE18'!D7) | R40: ='EMPLOYEE18'!AH23
B41: ='EMPLOYEE19'!A2 | C41: ='EMPLOYEE19'!AI23+'EMPLOYEE19'!AJ23 | D41: =N('EMPLOYEE19'!D5)+N('EMPLOYEE19'!D6) | E41: =REPT("█",ROUND(MIN(1,F41)*20,0))&REPT("░",20-ROUND(MIN(1,F41)*20,0)) | F41: =IF(D41=0,0,C41/D41) | G41: =IF(D41=0,"—",D41-C41) | H41: =SUM(INDEX('EMPLOYEE19'!$AI$11:$AM$22,MONTH(TODAY()),0)) | I41: =R41&" of "&Q41 | J41: ='EMPLOYEE19'!AI23 | K41: ='EMPLOYEE19'!AJ23 | L41: ='EMPLOYEE19'!AK23 | M41: ='EMPLOYEE19'!AL23 | N41: ='EMPLOYEE19'!AM23 | O41: =IF(D41=0,"Set allotment",IF(F41>=1,"Over",IF(F41>=0.8,"Running low","On track"))) | P41: =F41+(100-ROW())/100000 | Q41: =N('EMPLOYEE19'!D7) | R41: ='EMPLOYEE19'!AH23
B42: ='EMPLOYEE20'!A2 | C42: ='EMPLOYEE20'!AI23+'EMPLOYEE20'!AJ23 | D42: =N('EMPLOYEE20'!D5)+N('EMPLOYEE20'!D6) | E42: =REPT("█",ROUND(MIN(1,F42)*20,0))&REPT("░",20-ROUND(MIN(1,F42)*20,0)) | F42: =IF(D42=0,0,C42/D42) | G42: =IF(D42=0,"—",D42-C42) | H42: =SUM(INDEX('EMPLOYEE20'!$AI$11:$AM$22,MONTH(TODAY()),0)) | I42: =R42&" of "&Q42 | J42: ='EMPLOYEE20'!AI23 | K42: ='EMPLOYEE20'!AJ23 | L42: ='EMPLOYEE20'!AK23 | M42: ='EMPLOYEE20'!AL23 | N42: ='EMPLOYEE20'!AM23 | O42: =IF(D42=0,"Set allotment",IF(F42>=1,"Over",IF(F42>=0.8,"Running low","On track"))) | P42: =F42+(100-ROW())/100000 | Q42: =N('EMPLOYEE20'!D7) | R42: ='EMPLOYEE20'!AH23
B44: Allotments and names come from each employee's tab (cells A2, D5, D6, D7). Days come from the calendar codes on those tabs.

Sheet Summary
A1: 2026 Attendance Summary
A2: % of Annual Allotment Used/Planned
A4: Employee | B4: Category | C4: Annual Allotment | D4: Used/Planned | E4: Remaining | F4: % Used | H4: Label | I4: % Used
A5: EMPLOYEE1 | B5: PTO (incl. Banked) | C5: =EMPLOYEE1!D5+EMPLOYEE1!D6 | D5: =EMPLOYEE1!AI23+EMPLOYEE1!AJ23 | E5: =C5-D5 | F5: =IF(C5=0,0,D5/C5) | H5: =A5&" - "&B5 | I5: =F5
A6: EMPLOYEE1 | B6: Holiday | C6: =EMPLOYEE1!D7 | D6: =EMPLOYEE1!AH23 | E6: =C6-D6 | F6: =IF(C6=0,0,D6/C6) | H6: =A6&" - "&B6 | I6: =F6
A7: EMPLOYEE2 | B7: PTO (incl. Banked) | C7: =EMPLOYEE2!D5+EMPLOYEE2!D6 | D7: =EMPLOYEE2!AI23+EMPLOYEE2!AJ23 | E7: =C7-D7 | F7: =IF(C7=0,0,D7/C7) | H7: =A7&" - "&B7 | I7: =F7
A8: EMPLOYEE2 | B8: Holiday | C8: =EMPLOYEE2!D7 | D8: =EMPLOYEE2!AH23 | E8: =C8-D8 | F8: =IF(C8=0,0,D8/C8) | H8: =A8&" - "&B8 | I8: =F8
A9: EMPLOYEE3 | B9: PTO (incl. Banked) | C9: =EMPLOYEE3!D5+EMPLOYEE3!D6 | D9: =EMPLOYEE3!AI23+EMPLOYEE3!AJ23 | E9: =C9-D9 | F9: =IF(C9=0,0,D9/C9) | H9: =A9&" - "&B9 | I9: =F9
A10: EMPLOYEE3 | B10: Holiday | C10: =EMPLOYEE3!D7 | D10: =EMPLOYEE3!AH23 | E10: =C10-D10 | F10: =IF(C10=0,0,D10/C10) | H10: =A10&" - "&B10 | I10: =F10
A11: EMPLOYEE4 | B11: PTO (incl. Banked) | C11: =EMPLOYEE4!D5+EMPLOYEE4!D6 | D11: =EMPLOYEE4!AI23+EMPLOYEE4!AJ23 | E11: =C11-D11 | F11: =IF(C11=0,0,D11/C11) | H11: =A11&" - "&B11 | I11: =F11
A12: EMPLOYEE4 | B12: Holiday | C12: =EMPLOYEE4!D7 | D12: =EMPLOYEE4!AH23 | E12: =C12-D12 | F12: =IF(C12=0,0,D12/C12) | H12: =A12&" - "&B12 | I12: =F12
A13: EMPLOYEE5 | B13: PTO (incl. Banked) | C13: =EMPLOYEE5!D5+EMPLOYEE5!D6 | D13: =EMPLOYEE5!AI23+EMPLOYEE5!AJ23 | E13: =C13-D13 | F13: =IF(C13=0,0,D13/C13) | H13: =A13&" - "&B13 | I13: =F13
A14: EMPLOYEE5 | B14: Holiday | C14: =EMPLOYEE5!D7 | D14: =EMPLOYEE5!AH23 | E14: =C14-D14 | F14: =IF(C14=0,0,D14/C14) | H14: =A14&" - "&B14 | I14: =F14
A15: EMPLOYEE6 | B15: PTO (incl. Banked) | C15: =EMPLOYEE6!D5+EMPLOYEE6!D6 | D15: =EMPLOYEE6!AI23+EMPLOYEE6!AJ23 | E15: =C15-D15 | F15: =IF(C15=0,0,D15/C15) | H15: =A15&" - "&B15 | I15: =F15
A16: EMPLOYEE6 | B16: Holiday | C16: =EMPLOYEE6!D7 | D16: =EMPLOYEE6!AH23 | E16: =C16-D16 | F16: =IF(C16=0,0,D16/C16) | H16: =A16&" - "&B16 | I16: =F16
A17: EMPLOYEE7 | B17: PTO (incl. Banked) | C17: =EMPLOYEE7!D5+EMPLOYEE7!D6 | D17: =EMPLOYEE7!AI23+EMPLOYEE7!AJ23 | E17: =C17-D17 | F17: =IF(C17=0,0,D17/C17) | H17: =A17&" - "&B17 | I17: =F17
A18: EMPLOYEE7 | B18: Holiday | C18: =EMPLOYEE7!D7 | D18: =EMPLOYEE7!AH23 | E18: =C18-D18 | F18: =IF(C18=0,0,D18/C18) | H18: =A18&" - "&B18 | I18: =F18
A19: EMPLOYEE8 | B19: PTO (incl. Banked) | C19: =EMPLOYEE8!D5+EMPLOYEE8!D6 | D19: =EMPLOYEE8!AI23+EMPLOYEE8!AJ23 | E19: =C19-D19 | F19: =IF(C19=0,0,D19/C19) | H19: =A19&" - "&B19 | I19: =F19
A20: EMPLOYEE8 | B20: Holiday | C20: =EMPLOYEE8!D7 | D20: =EMPLOYEE8!AH23 | E20: =C20-D20 | F20: =IF(C20=0,0,D20/C20) | H20: =A20&" - "&B20 | I20: =F20
A21: EMPLOYEE9 | B21: PTO (incl. Banked) | C21: =EMPLOYEE9!D5+EMPLOYEE9!D6 | D21: =EMPLOYEE9!AI23+EMPLOYEE9!AJ23 | E21: =C21-D21 | F21: =IF(C21=0,0,D21/C21) | H21: =A21&" - "&B21 | I21: =F21
A22: EMPLOYEE9 | B22: Holiday | C22: =EMPLOYEE9!D7 | D22: =EMPLOYEE9!AH23 | E22: =C22-D22 | F22: =IF(C22=0,0,D22/C22) | H22: =A22&" - "&B22 | I22: =F22
A23: EMPLOYEE10 | B23: PTO (incl. Banked) | C23: =EMPLOYEE10!D5+EMPLOYEE10!D6 | D23: =EMPLOYEE10!AI23+EMPLOYEE10!AJ23 | E23: =C23-D23 | F23: =IF(C23=0,0,D23/C23) | H23: =A23&" - "&B23 | I23: =F23
A24: EMPLOYEE10 | B24: Holiday | C24: =EMPLOYEE10!D7 | D24: =EMPLOYEE10!AH23 | E24: =C24-D24 | F24: =IF(C24=0,0,D24/C24) | H24: =A24&" - "&B24 | I24: =F24
A25: EMPLOYEE11 | B25: PTO (incl. Banked) | C25: =EMPLOYEE11!D5+EMPLOYEE11!D6 | D25: =EMPLOYEE11!AI23+EMPLOYEE11!AJ23 | E25: =C25-D25 | F25: =IF(C25=0,0,D25/C25) | H25: =A25&" - "&B25 | I25: =F25
A26: EMPLOYEE11 | B26: Holiday | C26: =EMPLOYEE11!D7 | D26: =EMPLOYEE11!AH23 | E26: =C26-D26 | F26: =IF(C26=0,0,D26/C26) | H26: =A26&" - "&B26 | I26: =F26
A27: EMPLOYEE12 | B27: PTO (incl. Banked) | C27: =EMPLOYEE12!D5+EMPLOYEE12!D6 | D27: =EMPLOYEE12!AI23+EMPLOYEE12!AJ23 | E27: =C27-D27 | F27: =IF(C27=0,0,D27/C27) | H27: =A27&" - "&B27 | I27: =F27
A28: EMPLOYEE12 | B28: Holiday | C28: =EMPLOYEE12!D7 | D28: =EMPLOYEE12!AH23 | E28: =C28-D28 | F28: =IF(C28=0,0,D28/C28) | H28: =A28&" - "&B28 | I28: =F28
A29: EMPLOYEE13 | B29: PTO (incl. Banked) | C29: =EMPLOYEE13!D5+EMPLOYEE13!D6 | D29: =EMPLOYEE13!AI23+EMPLOYEE13!AJ23 | E29: =C29-D29 | F29: =IF(C29=0,0,D29/C29) | H29: =A29&" - "&B29 | I29: =F29
A30: EMPLOYEE13 | B30: Holiday | C30: =EMPLOYEE13!D7 | D30: =EMPLOYEE13!AH23 | E30: =C30-D30 | F30: =IF(C30=0,0,D30/C30) | H30: =A30&" - "&B30 | I30: =F30
A31: EMPLOYEE14 | B31: PTO (incl. Banked) | C31: =EMPLOYEE14!D5+EMPLOYEE14!D6 | D31: =EMPLOYEE14!AI23+EMPLOYEE14!AJ23 | E31: =C31-D31 | F31: =IF(C31=0,0,D31/C31) | H31: =A31&" - "&B31 | I31: =F31
A32: EMPLOYEE14 | B32: Holiday | C32: =EMPLOYEE14!D7 | D32: =EMPLOYEE14!AH23 | E32: =C32-D32 | F32: =IF(C32=0,0,D32/C32) | H32: =A32&" - "&B32 | I32: =F32
A33: EMPLOYEE15 | B33: PTO (incl. Banked) | C33: =EMPLOYEE15!D5+EMPLOYEE15!D6 | D33: =EMPLOYEE15!AI23+EMPLOYEE15!AJ23 | E33: =C33-D33 | F33: =IF(C33=0,0,D33/C33) | H33: =A33&" - "&B33 | I33: =F33
A34: EMPLOYEE15 | B34: Holiday | C34: =EMPLOYEE15!D7 | D34: =EMPLOYEE15!AH23 | E34: =C34-D34 | F34: =IF(C34=0,0,D34/C34) | H34: =A34&" - "&B34 | I34: =F34
A35: EMPLOYEE16 | B35: PTO (incl. Banked) | C35: =EMPLOYEE16!D5+EMPLOYEE16!D6 | D35: =EMPLOYEE16!AI23+EMPLOYEE16!AJ23 | E35: =C35-D35 | F35: =IF(C35=0,0,D35/C35) | H35: =A35&" - "&B35 | I35: =F35
A36: EMPLOYEE16 | B36: Holiday | C36: =EMPLOYEE16!D7 | D36: =EMPLOYEE16!AH23 | E36: =C36-D36 | F36: =IF(C36=0,0,D36/C36) | H36: =A36&" - "&B36 | I36: =F36
A37: EMPLOYEE17 | B37: PTO (incl. Banked) | C37: =EMPLOYEE17!D5+EMPLOYEE17!D6 | D37: =EMPLOYEE17!AI23+EMPLOYEE17!AJ23 | E37: =C37-D37 | F37: =IF(C37=0,0,D37/C37) | H37: =A37&" - "&B37 | I37: =F37
A38: EMPLOYEE17 | B38: Holiday | C38: =EMPLOYEE17!D7 | D38: =EMPLOYEE17!AH23 | E38: =C38-D38 | F38: =IF(C38=0,0,D38/C38) | H38: =A38&" - "&B38 | I38: =F38
A39: EMPLOYEE18 | B39: PTO (incl. Banked) | C39: =EMPLOYEE18!D5+EMPLOYEE18!D6 | D39: =EMPLOYEE18!AI23+EMPLOYEE18!AJ23 | E39: =C39-D39 | F39: =IF(C39=0,0,D39/C39) | H39: =A39&" - "&B39 | I39: =F39
A40: EMPLOYEE18 | B40: Holiday | C40: =EMPLOYEE18!D7 | D40: =EMPLOYEE18!AH23 | E40: =C40-D40 | F40: =IF(C40=0,0,D40/C40) | H40: =A40&" - "&B40 | I40: =F40
A41: EMPLOYEE19 | B41: PTO (incl. Banked) | C41: =EMPLOYEE19!D5+EMPLOYEE19!D6 | D41: =EMPLOYEE19!AI23+EMPLOYEE19!AJ23 | E41: =C41-D41 | F41: =IF(C41=0,0,D41/C41) | H41: =A41&" - "&B41 | I41: =F41
...

Sheet EMPLOYEE1
A1: 2026 Time Off Calendar
A2: EMPLOYEE1
D4: 2026 | F4: Used/ Planned | H4: Balance | J4: Rollover
A5: PTO | F5: =AI23 | H5: =D5-F5 | M5: P | N5: PTO | S5: H | T5: Holiday | Z5: Sat/Sun
A6: Banked PTO | F6: =AJ23 | H6: =D6-F6 | J6: =IF(H5>10,IF(H6+10>20,20,H6+10),IF(H6+H5>20,20,H6+H5)) | M6: PH | N6: 1/2 PTO | S6: B | T6: Bereavement | Y6: R | Z6: Remote
A7: Holiday | D7: 10 | F7: =AH23 | H7: =D7-F7 | M7: PB | N7: Banked PTO | S7: J | T7: Jury Duty
M8: PBH | N8: 1/2 Banked PTO | S8: T | T8: Training
AH9: Total Used/Planned
B10: 1 | C10: 2 | D10: 3 | E10: 4 | F10: 5 | G10: 6 | H10: 7 | I10: 8 | J10: 9 | K10: 10 | L10: 11 | M10: 12 | N10: 13 | O10: 14 | P10: 15 | Q10: 16 | R10: 17 | S10: 18 | T10: 19 | U10: 20 | V10: 21 | W10: 22 | X10: 23 | Y10: 24 | Z10: 25 | AA10: 26 | AB10: 27 | AC10: 28 | AD10: 29 | AE10: 30 | AF10: 31 | AH10: H | AI10: P | AJ10: PB | AK10: B | AL10: J | AM10: T
A11: JAN | B11: H | AH11: =COUNTIF($B11:$AF11,"H") | AI11: =COUNTIF($B11:$AF11,"P")+COUNTIF($B11:$AF11,"PH")*0.5 | AJ11: =COUNTIF($B11:$AF11,"PB")+COUNTIF($B11:$AF11,"PBH")*0.5 | AK11: =COUNTIF($B11:$AF11,"B") | AL11: =COUNTIF($B11:$AF11,"J") | AM11: =COUNTIF($B11:$AF11,"T")
A12: FEB | AH12: =COUNTIF($B12:$AF12,"H") | AI12: =COUNTIF($B12:$AF12,"P")+COUNTIF($B12:$AF12,"PH")*0.5 | AJ12: =COUNTIF($B12:$AF12,"PB")+COUNTIF($B12:$AF12,"PBH")*0.5 | AK12: =COUNTIF($B12:$AF12,"B") | AL12: =COUNTIF($B12:$AF12,"J") | AM12: =COUNTIF($B12:$AF12,"T")
A13: MAR | AH13: =COUNTIF($B13:$AF13,"H") | AI13: =COUNTIF($B13:$AF13,"P")+COUNTIF($B13:$AF13,"PH")*0.5 | AJ13: =COUNTIF($B13:$AF13,"PB")+COUNTIF($B13:$AF13,"PBH")*0.5 | AK13: =COUNTIF($B13:$AF13,"B") | AL13: =COUNTIF($B13:$AF13,"J") | AM13: =COUNTIF($B13:$AF13,"T")
A14: APR | AH14: =COUNTIF($B14:$AF14,"H") | AI14: =COUNTIF($B14:$AF14,"P")+COUNTIF($B14:$AF14,"PH")*0.5 | AJ14: =COUNTIF($B14:$AF14,"PB")+COUNTIF($B14:$AF14,"PBH")*0.5 | AK14: =COUNTIF($B14:$AF14,"B") | AL14: =COUNTIF($B14:$AF14,"J") | AM14: =COUNTIF($B14:$AF14,"T")
A15: MAY | Z15: H | AH15: =COUNTIF($B15:$AF15,"H") | AI15: =COUNTIF($B15:$AF15,"P")+COUNTIF($B15:$AF15,"PH")*0.5 | AJ15: =COUNTIF($B15:$AF15,"PB")+COUNTIF($B15:$AF15,"PBH")*0.5 | AK15: =COUNTIF($B15:$AF15,"B") | AL15: =COUNTIF($B15:$AF15,"J") | AM15: =COUNTIF($B15:$AF15,"T")
A16: JUN | E16: H | AH16: =COUNTIF($B16:$AF16,"H") | AI16: =COUNTIF($B16:$AF16,"P")+COUNTIF($B16:$AF16,"PH")*0.5 | AJ16: =COUNTIF($B16:$AF16,"PB")+COUNTIF($B16:$AF16,"PBH")*0.5 | AK16: =COUNTIF($B16:$AF16,"B") | AL16: =COUNTIF($B16:$AF16,"J") | AM16: =COUNTIF($B16:$AF16,"T")
A17: JUL | AH17: =COUNTIF($B17:$AF17,"H") | AI17: =COUNTIF($B17:$AF17,"P")+COUNTIF($B17:$AF17,"PH")*0.5 | AJ17: =COUNTIF($B17:$AF17,"PB")+COUNTIF($B17:$AF17,"PBH")*0.5 | AK17: =COUNTIF($B17:$AF17,"B") | AL17: =COUNTIF($B17:$AF17,"J") | AM17: =COUNTIF($B17:$AF17,"T")
A18: AUG | AH18: =COUNTIF($B18:$AF18,"H") | AI18: =COUNTIF($B18:$AF18,"P")+COUNTIF($B18:$AF18,"PH")*0.5 | AJ18: =COUNTIF($B18:$AF18,"PB")+COUNTIF($B18:$AF18,"PBH")*0.5 | AK18: =COUNTIF($B18:$AF18,"B") | AL18: =COUNTIF($B18:$AF18,"J") | AM18: =COUNTIF($B18:$AF18,"T")
A19: SEP | H19: H | AH19: =COUNTIF($B19:$AF19,"H") | AI19: =COUNTIF($B19:$AF19,"P")+COUNTIF($B19:$AF19,"PH")*0.5 | AJ19: =COUNTIF($B19:$AF19,"PB")+COUNTIF($B19:$AF19,"PBH")*0.5 | AK19: =COUNTIF($B19:$AF19,"B") | AL19: =COUNTIF($B19:$AF19,"J") | AM19: =COUNTIF($B19:$AF19,"T")
A20: OCT | AH20: =COUNTIF($B20:$AF20,"H") | AI20: =COUNTIF($B20:$AF20,"P")+COUNTIF($B20:$AF20,"PH")*0.5 | AJ20: =COUNTIF($B20:$AF20,"PB")+COUNTIF($B20:$AF20,"PBH")*0.5 | AK20: =COUNTIF($B20:$AF20,"B") | AL20: =COUNTIF($B20:$AF20,"J") | AM20: =COUNTIF($B20:$AF20,"T")
A21: NOV | AA21: H | AH21: =COUNTIF($B21:$AF21,"H") | AI21: =COUNTIF($B21:$AF21,"P")+COUNTIF($B21:$AF21,"PH")*0.5 | AJ21: =COUNTIF($B21:$AF21,"PB")+COUNTIF($B21:$AF21,"PBH")*0.5 | AK21: =COUNTIF($B21:$AF21,"B") | AL21: =COUNTIF($B21:$AF21,"J") | AM21: =COUNTIF($B21:$AF21,"T")
A22: DEC | Z22: H | AH22: =COUNTIF($B22:$AF22,"H") | AI22: =COUNTIF($B22:$AF22,"P")+COUNTIF($B22:$AF22,"PH")*0.5 | AJ22: =COUNTIF($B22:$AF22,"PB")+COUNTIF($B22:$AF22,"PBH")*0.5 | AK22: =COUNTIF($B22:$AF22,"B") | AL22: =COUNTIF($B22:$AF22,"J") | AM22: =COUNTIF($B22:$AF22,"T")
AH23: =SUM(AH11:AH22) | AI23: =SUM(AI11:AI22) | AJ23: =SUM(AJ11:AJ22) | AK23: =SUM(AK11:AK22) | AL23: =SUM(AL11:AL22) | AM23: =SUM(AM11:AM22)

Sheet EMPLOYEE2
A1: 2026 Time Off Calendar
A2: EMPLOYEE2
D4: 2026 | F4: Used/ Planned | H4: Balance | J4: Rollover
A5: PTO | F5: =AI23 | H5: =D5-F5 | M5: P | N5: PTO | S5: H | T5: Holiday | Z5: Sat/Sun
A6: Banked PTO | F6: =AJ23 | H6: =D6-F6 | J6: =IF(H5>10,IF(H6+10>20,20,H6+10),IF(H6+H5>20,20,H6+H5)) | M6: PH | N6: 1/2 PTO | S6: B | T6: Bereavement | Y6: R | Z6: Remote
A7: Holiday | D7: 10 | F7: =AH23 | H7: =D7-F7 | M7: PB | N7: Banked PTO | S7: J | T7: Jury Duty
M8: PBH | N8: 1/2 Banked PTO | S8: T | T8: Training
AH9: Total Used/Planned
B10: 1 | C10: 2 | D10: 3 | E10: 4 | F10: 5 | G10: 6 | H10: 7 | I10: 8 | J10: 9 | K10: 10 | L10: 11 | M10: 12 | N10: 13 | O10: 14 | P10: 15 | Q10: 16 | R10: 17 | S10: 18 | T10: 19 | U10: 20 | V10: 21 | W10: 22 | X10: 23 | Y10: 24 | Z10: 25 | AA10: 26 | AB10: 27 | AC10: 28 | AD10: 29 | AE10: 30 | AF10: 31 | AH10: H | AI10: P | AJ10: PB | AK10: B | AL10: J | AM10: T
A11: JAN | B11: H | AH11: =COUNTIF($B11:$AF11,"H") | AI11: =COUNTIF($B11:$AF11,"P")+COUNTIF($B11:$AF11,"PH")*0.5 | AJ11: =COUNTIF($B11:$AF11,"PB")+COUNTIF($B11:$AF11,"PBH")*0.5 | AK11: =COUNTIF($B11:$AF11,"B") | AL11: =COUNTIF($B11:$AF11,"J") | AM11: =COUNTIF($B11:$AF11,"T")
A12: FEB | AH12: =COUNTIF($B12:$AF12,"H") | AI12: =COUNTIF($B12:$AF12,"P")+COUNTIF($B12:$AF12,"PH")*0.5 | AJ12: =COUNTIF($B12:$AF12,"PB")+COUNTIF($B12:$AF12,"PBH")*0.5 | AK12: =COUNTIF($B12:$AF12,"B") | AL12: =COUNTIF($B12:$AF12,"J") | AM12: =COUNTIF($B12:$AF12,"T")
A13: MAR | AH13: =COUNTIF($B13:$AF13,"H") | AI13: =COUNTIF($B13:$AF13,"P")+COUNTIF($B13:$AF13,"PH")*0.5 | AJ13: =COUNTIF($B13:$AF13,"PB")+COUNTIF($B13:$AF13,"PBH")*0.5 | AK13: =COUNTIF($B13:$AF13,"B") | AL13: =COUNTIF($B13:$AF13,"J") | AM13: =COUNTIF($B13:$AF13,"T")
A14: APR | AH14: =COUNTIF($B14:$AF14,"H") | AI14: =COUNTIF($B14:$AF14,"P")+COUNTIF($B14:$AF14,"PH")*0.5 | AJ14: =COUNTIF($B14:$AF14,"PB")+COUNTIF($B14:$AF14,"PBH")*0.5 | AK14: =COUNTIF($B14:$AF14,"B") | AL14: =COUNTIF($B14:$AF14,"J") | AM14: =COUNTIF($B14:$AF14,"T")
A15: MAY | Z15: H | AH15: =COUNTIF($B15:$AF15,"H") | AI15: =COUNTIF($B15:$AF15,"P")+COUNTIF($B15:$AF15,"PH")*0.5 | AJ15: =COUNTIF($B15:$AF15,"PB")+COUNTIF($B15:$AF15,"PBH")*0.5 | AK15: =COUNTIF($B15:$AF15,"B") | AL15: =COUNTIF($B15:$AF15,"J") | AM15: =COUNTIF($B15:$AF15,"T")
A16: JUN | E16: H | AH16: =COUNTIF($B16:$AF16,"H") | AI16: =COUNTIF($B16:$AF16,"P")+COUNTIF($B16:$AF16,"PH")*0.5 | AJ16: =COUNTIF($B16:$AF16,"PB")+COUNTIF($B16:$AF16,"PBH")*0.5 | AK16: =COUNTIF($B16:$AF16,"B") | AL16: =COUNTIF($B16:$AF16,"J") | AM16: =COUNTIF($B16:$AF16,"T")
A17: JUL | AH17: =COUNTIF($B17:$AF17,"H") | AI17: =COUNTIF($B17:$AF17,"P")+COUNTIF($B17:$AF17,"PH")*0.5 | AJ17: =COUNTIF($B17:$AF17,"PB")+COUNTIF($B17:$AF17,"PBH")*0.5 | AK17: =COUNTIF($B17:$AF17,"B") | AL17: =COUNTIF($B17:$AF17,"J") | AM17: =COUNTIF($B17:$AF17,"T")
A18: AUG | AH18: =COUNTIF($B18:$AF18,"H") | AI18: =COUNTIF($B18:$AF18,"P")+COUNTIF($B18:$AF18,"PH")*0.5 | AJ18: =COUNTIF($B18:$AF18,"PB")+COUNTIF($B18:$AF18,"PBH")*0.5 | AK18: =COUNTIF($B18:$AF18,"B") | AL18: =COUNTIF($B18:$AF18,"J") | AM18: =COUNTIF($B18:$AF18,"T")
A19: SEP | H19: H | AH19: =COUNTIF($B19:$AF19,"H") | AI19: =COUNTIF($B19:$AF19,"P")+COUNTIF($B19:$AF19,"PH")*0.5 | AJ19: =COUNTIF($B19:$AF19,"PB")+COUNTIF($B19:$AF19,"PBH")*0.5 | AK19: =COUNTIF($B19:$AF19,"B") | AL19: =COUNTIF($B19:$AF19,"J") | AM19: =COUNTIF($B19:$AF19,"T")
A20: OCT | AH20: =COUNTIF($B20:$AF20,"H") | AI20: =COUNTIF($B20:$AF20,"P")+COUNTIF($B20:$AF20,"PH")*0.5 | AJ20: =COUNTIF($B20:$AF20,"PB")+COUNTIF($B20:$AF20,"PBH")*0.5 | AK20: =COUNTIF($B20:$AF20,"B") | AL20: =COUNTIF($B20:$AF20,"J") | AM20: =COUNTIF($B20:$AF20,"T")
A21: NOV | AA21: H | AH21: =COUNTIF($B21:$AF21,"H") | AI21: =COUNTIF($B21:$AF21,"P")+COUNTIF($B21:$AF21,"PH")*0.5 | AJ21: =COUNTIF($B21:$AF21,"PB")+COUNTIF($B21:$AF21,"PBH")*0.5 | AK21: =COUNTIF($B21:$AF21,"B") | AL21: =COUNTIF($B21:$AF21,"J") | AM21: =COUNTIF($B21:$AF21,"T")
A22: DEC | Z22: H | AH22: =COUNTIF($B22:$AF22,"H") | AI22: =COUNTIF($B22:$AF22,"P")+COUNTIF($B22:$AF22,"PH")*0.5 | AJ22: =COUNTIF($B22:$AF22,"PB")+COUNTIF($B22:$AF22,"PBH")*0.5 | AK22: =COUNTIF($B22:$AF22,"B") | AL22: =COUNTIF($B22:$AF22,"J") | AM22: =COUNTIF($B22:$AF22,"T")
AH23: =SUM(AH11:AH22) | AI23: =SUM(AI11:AI22) | AJ23: =SUM(AJ11:AJ22) | AK23: =SUM(AK11:AK22) | AL23: =SUM(AL11:AL22) | AM23: =SUM(AM11:AM22)

Sheet EMPLOYEE3
A1: 2026 Time Off Calendar
A2: EMPLOYEE3
D4: 2026 | F4: Used/ Planned | H4: Balance | J4: Rollover
A5: PTO | F5: =AI23 | H5: =D5-F5 | M5: P | N5: PTO | S5: H | T5: Holiday | Z5: Sat/Sun
A6: Banked PTO | F6: =AJ23 | H6: =D6-F6 | J6: =IF(H5>10,IF(H6+10>20,20,H6+10),IF(H6+H5>20,20,H6+H5)) | M6: PH | N6: 1/2 PTO | S6: B | T6: Bereavement | Y6: R | Z6: Remote
A7: Holiday | D7: 10 | F7: =AH23 | H7: =D7-F7 | M7: PB | N7: Banked PTO | S7: J | T7: Jury Duty
M8: PBH | N8: 1/2 Banked PTO | S8: T | T8: Training
AH9: Total Used/Planned
B10: 1 | C10: 2 | D10: 3 | E10: 4 | F10: 5 | G10: 6 | H10: 7 | I10: 8 | J10: 9 | K10: 10 | L10: 11 | M10: 12 | N10: 13 | O10: 14 | P10: 15 | Q10: 16 | R10: 17 | S10: 18 | T10: 19 | U10: 20 | V10: 21 | W10: 22 | X10: 23 | Y10: 24 | Z10: 25 | AA10: 26 | AB10: 27 | AC10: 28 | AD10: 29 | AE10: 30 | AF10: 31 | AH10: H | AI10: P | AJ10: PB | AK10: B | AL10: J | AM10: T
A11: JAN | B11: H | AH11: =COUNTIF($B11:$AF11,"H") | AI11: =COUNTIF($B11:$AF11,"P")+COUNTIF($B11:$AF11,"PH")*0.5 | AJ11: =COUNTIF($B11:$AF11,"PB")+COUNTIF($B11:$AF11,"PBH")*0.5 | AK11: =COUNTIF($B11:$AF11,"B") | AL11: =COUNTIF($B11:$AF11,"J") | AM11: =COUNTIF($B11:$AF11,"T")
A12: FEB | AH12: =COUNTIF($B12:$AF12,"H") | AI12: =COUNTIF($B12:$AF12,"P")+COUNTIF($B12:$AF12,"PH")*0.5 | AJ12: =COUNTIF($B12:$AF12,"PB")+COUNTIF($B12:$AF12,"PBH")*0.5 | AK12: =COUNTIF($B12:$AF12,"B") | AL12: =COUNTIF($B12:$AF12,"J") | AM12: =COUNTIF($B12:$AF12,"T")
A13: MAR | AH13: =COUNTIF($B13:$AF13,"H") | AI13: =COUNTIF($B13:$AF13,"P")+COUNTIF($B13:$AF13,"PH")*0.5 | AJ13: =COUNTIF($B13:$AF13,"PB")+COUNTIF($B13:$AF13,"PBH")*0.5 | AK13: =COUNTIF($B13:$AF13,"B") | AL13: =COUNTIF($B13:$AF13,"J") | AM13: =COUNTIF($B13:$AF13,"T")
A14: APR | AH14: =COUNTIF($B14:$AF14,"H") | AI14: =COUNTIF($B14:$AF14,"P")+COUNTIF($B14:$AF14,"PH")*0.5 | AJ14: =COUNTIF($B14:$AF14,"PB")+COUNTIF($B14:$AF14,"PBH")*0.5 | AK14: =COUNTIF($B14:$AF14,"B") | AL14: =COUNTIF($B14:$AF14,"J") | AM14: =COUNTIF($B14:$AF14,"T")
A15: MAY | Z15: H | AH15: =COUNTIF($B15:$AF15,"H") | AI15: =COUNTIF($B15:$AF15,"P")+COUNTIF($B15:$AF15,"PH")*0.5 | AJ15: =COUNTIF($B15:$AF15,"PB")+COUNTIF($B15:$AF15,"PBH")*0.5 | AK15: =COUNTIF($B15:$AF15,"B") | AL15: =COUNTIF($B15:$AF15,"J") | AM15: =COUNTIF($B15:$AF15,"T")
A16: JUN | E16: H | AH16: =COUNTIF($B16:$AF16,"H") | AI16: =COUNTIF($B16:$AF16,"P")+COUNTIF($B16:$AF16,"PH")*0.5 | AJ16: =COUNTIF($B16:$AF16,"PB")+COUNTIF($B16:$AF16,"PBH")*0.5 | AK16: =COUNTIF($B16:$AF16,"B") | AL16: =COUNTIF($B16:$AF16,"J") | AM16: =COUNTIF($B16:$AF16,"T")
A17: JUL | AH17: =COUNTIF($B17:$AF17,"H") | AI17: =COUNTIF($B17:$AF17,"P")+COUNTIF($B17:$AF17,"PH")*0.5 | AJ17: =COUNTIF($B17:$AF17,"PB")+COUNTIF($B17:$AF17,"PBH")*0.5 | AK17: =COUNTIF($B17:$AF17,"B") | AL17: =COUNTIF($B17:$AF17,"J") | AM17: =COUNTIF($B17:$AF17,"T")
A18: AUG | AH18: =COUNTIF($B18:$AF18,"H") | AI18: =COUNTIF($B18:$AF18,"P")+COUNTIF($B18:$AF18,"PH")*0.5 | AJ18: =COUNTIF($B18:$AF18,"PB")+COUNTIF($B18:$AF18,"PBH")*0.5 | AK18: =COUNTIF($B18:$AF18,"B") | AL18: =COUNTIF($B18:$AF18,"J") | AM18: =COUNTIF($B18:$AF18,"T")
A19: SEP | H19: H | AH19: =COUNTIF($B19:$AF19,"H") | AI19: =COUNTIF($B19:$AF19,"P")+COUNTIF($B19:$AF19,"PH")*0.5 | AJ19: =COUNTIF($B19:$AF19,"PB")+COUNTIF($B19:$AF19,"PBH")*0.5 | AK19: =COUNTIF($B19:$AF19,"B") | AL19: =COUNTIF($B19:$AF19,"J") | AM19: =COUNTIF($B19:$AF19,"T")
A20: OCT | AH20: =COUNTIF($B20:$AF20,"H") | AI20: =COUNTIF($B20:$AF20,"P")+COUNTIF($B20:$AF20,"PH")*0.5 | AJ20: =COUNTIF($B20:$AF20,"PB")+COUNTIF($B20:$AF20,"PBH")*0.5 | AK20: =COUNTIF($B20:$AF20,"B") | AL20: =COUNTIF($B20:$AF20,"J") | AM20: =COUNTIF($B20:$AF20,"T")
A21: NOV | AA21: H | AH21: =COUNTIF($B21:$AF21,"H") | AI21: =COUNTIF($B21:$AF21,"P")+COUNTIF($B21:$AF21,"PH")*0.5 | AJ21: =COUNTIF($B21:$AF21,"PB")+COUNTIF($B21:$AF21,"PBH")*0.5 | AK21: =COUNTIF($B21:$AF21,"B") | AL21: =COUNTIF($B21:$AF21,"J") | AM21: =COUNTIF($B21:$AF21,"T")
A22: DEC | Z22: H | AH22: =COUNTIF($B22:$AF22,"H") | AI22: =COUNTIF($B22:$AF22,"P")+COUNTIF($B22:$AF22,"PH")*0.5 | AJ22: =COUNTIF($B22:$AF22,"PB")+COUNTIF($B22:$AF22,"PBH")*0.5 | AK22: =COUNTIF($B22:$AF22,"B") | AL22: =COUNTIF($B22:$AF22,"J") | AM22: =COUNTIF($B22:$AF22,"T")
AH23: =SUM(AH11:AH22) | AI23: =SUM(AI11:AI22) | AJ23: =SUM(AJ11:AJ22) | AK23: =SUM(AK11:AK22) | AL23: =SUM(AL11:AL22) | AM23: =SUM(AM11:AM22)

Sheet EMPLOYEE4
A1: 2026 Time Off Calendar
A2: EMPLOYEE4
D4: 2026 | F4: Used/ Planned | H4: Balance | J4: Rollover
A5: PTO | F5: =AI23 | H5: =D5-F5 | M5: P | N5: PTO | S5: H | T5: Holiday | Z5: Sat/Sun
A6: Banked PTO | F6: =AJ23 | H6: =D6-F6 | J6: =IF(H5>10,IF(H6+10>20,20,H6+10),IF(H6+H5>20,20,H6+H5)) | M6: PH | N6: 1/2 PTO | S6: B | T6: Bereavement | Y6: R | Z6: Remote
A7: Holiday | D7: 10 | F7: =AH23 | H7: =D7-F7 | M7: PB | N7: Banked PTO | S7: J | T7: Jury Duty
M8: PBH | N8: 1/2 Banked PTO | S8: T | T8: Training
AH9: Total Used/Planned
B10: 1 | C10: 2 | D10: 3 | E10: 4 | F10: 5 | G10: 6 | H10: 7 | I10: 8 | J10: 9 | K10: 10 | L10: 11 | M10: 12 | N10: 13 | O10: 14 | P10: 15 | Q10: 16 | R10: 17 | S10: 18 | T10: 19 | U10: 20 | V10: 21 | W10: 22 | X10: 23 | Y10: 24 | Z10: 25 | AA10: 26 | AB10: 27 | AC10: 28 | AD10: 29 | AE10: 30 | AF10: 31 | AH10: H | AI10: P | AJ10: PB | AK10: B | AL10: J | AM10: T
A11: JAN | B11: H | AH11: =COUNTIF($B11:$AF11,"H") | AI11: =COUNTIF($B11:$AF11,"P")+COUNTIF($B11:$AF11,"PH")*0.5 | AJ11: =COUNTIF($B11:$AF11,"PB")+COUNTIF($B11:$AF11,"PBH")*0.5 | AK11: =COUNTIF($B11:$AF11,"B") | AL11: =COUNTIF($B11:$AF11,"J") | AM11: =COUNTIF($B11:$AF11,"T")
A12: FEB | AH12: =COUNTIF($B12:$AF12,"H") | AI12: =COUNTIF($B12:$AF12,"P")+COUNTIF($B12:$AF12,"PH")*0.5 | AJ12: =COUNTIF($B12:$AF12,"PB")+COUNTIF($B12:$AF12,"PBH")*0.5 | AK12: =COUNTIF($B12:$AF12,"B") | AL12: =COUNTIF($B12:$AF12,"J") | AM12: =COUNTIF($B12:$AF12,"T")
A13: MAR | AH13: =COUNTIF($B13:$AF13,"H") | AI13: =COUNTIF($B13:$AF13,"P")+COUNTIF($B13:$AF13,"PH")*0.5 | AJ13: =COUNTIF($B13:$AF13,"PB")+COUNTIF($B13:$AF13,"PBH")*0.5 | AK13: =COUNTIF($B13:$AF13,"B") | AL13: =COUNTIF($B13:$AF13,"J") | AM13: =COUNTIF($B13:$AF13,"T")
A14: APR | AH14: =COUNTIF($B14:$AF14,"H") | AI14: =COUNTIF($B14:$AF14,"P")+COUNTIF($B14:$AF14,"PH")*0.5 | AJ14: =COUNTIF($B14:$AF14,"PB")+COUNTIF($B14:$AF14,"PBH")*0.5 | AK14: =COUNTIF($B14:$AF14,"B") | AL14: =COUNTIF($B14:$AF14,"J") | AM14: =COUNTIF($B14:$AF14,"T")
A15: MAY | Z15: H | AH15: =COUNTIF($B15:$AF15,"H") | AI15: =COUNTIF($B15:$AF15,"P")+COUNTIF($B15:$AF15,"PH")*0.5 | AJ15: =COUNTIF($B15:$AF15,"PB")+COUNTIF($B15:$AF15,"PBH")*0.5 | AK15: =COUNTIF($B15:$AF15,"B") | AL15: =COUNTIF($B15:$AF15,"J") | AM15: =COUNTIF($B15:$AF15,"T")
A16: JUN | E16: H | AH16: =COUNTIF($B16:$AF16,"H") | AI16: =COUNTIF($B16:$AF16,"P")+COUNTIF($B16:$AF16,"PH")*0.5 | AJ16: =COUNTIF($B16:$AF16,"PB")+COUNTIF($B16:$AF16,"PBH")*0.5 | AK16: =COUNTIF($B16:$AF16,"B") | AL16: =COUNTIF($B16:$AF16,"J") | AM16: =COUNTIF($B16:$AF16,"T")
A17: JUL | AH17: =COUNTIF($B17:$AF17,"H") | AI17: =COUNTIF($B17:$AF17,"P")+COUNTIF($B17:$AF17,"PH")*0.5 | AJ17: =COUNTIF($B17:$AF17,"PB")+COUNTIF($B17:$AF17,"PBH")*0.5 | AK17: =COUNTIF($B17:$AF17,"B") | AL17: =COUNTIF($B17:$AF17,"J") | AM17: =COUNTIF($B17:$AF17,"T")
A18: AUG | AH18: =COUNTIF($B18:$AF18,"H") | AI18: =COUNTIF($B18:$AF18,"P")+COUNTIF($B18:$AF18,"PH")*0.5 | AJ18: =COUNTIF($B18:$AF18,"PB")+COUNTIF($B18:$AF18,"PBH")*0.5 | AK18: =COUNTIF($B18:$AF18,"B") | AL18: =COUNTIF($B18:$AF18,"J") | AM18: =COUNTIF($B18:$AF18,"T")
A19: SEP | H19: H | AH19: =COUNTIF($B19:$AF19,"H") | AI19: =COUNTIF($B19:$AF19,"P")+COUNTIF($B19:$AF19,"PH")*0.5 | AJ19: =COUNTIF($B19:$AF19,"PB")+COUNTIF($B19:$AF19,"PBH")*0.5 | AK19: =COUNTIF($B19:$AF19,"B") | AL19: =COUNTIF($B19:$AF19,"J") | AM19: =COUNTIF($B19:$AF19,"T")
A20: OCT | AH20: =COUNTIF($B20:$AF20,"H") | AI20: =COUNTIF($B20:$AF20,"P")+COUNTIF($B20:$AF20,"PH")*0.5 | AJ20: =COUNTIF($B20:$AF20,"PB")+COUNTIF($B20:$AF20,"PBH")*0.5 | AK20: =COUNTIF($B20:$AF20,"B") | AL20: =COUNTIF($B20:$AF20,"J") | AM20: =COUNTIF($B20:$AF20,"T")
A21: NOV | AA21: H | AH21: =COUNTIF($B21:$AF21,"H") | AI21: =COUNTIF($B21:$AF21,"P")+COUNTIF($B21:$AF21,"PH")*0.5 | AJ21: =COUNTIF($B21:$AF21,"PB")+COUNTIF($B21:$AF21,"PBH")*0.5 | AK21: =COUNTIF($B21:$AF21,"B") | AL21: =COUNTIF($B21:$AF21,"J") | AM21: =COUNTIF($B21:$AF21,"T")
A22: DEC | Z22: H | AH22: =COUNTIF($B22:$AF22,"H") | AI22: =COUNTIF($B22:$AF22,"P")+COUNTIF($B22:$AF22,"PH")*0.5 | AJ22: =COUNTIF($B22:$AF22,"PB")+COUNTIF($B22:$AF22,"PBH")*0.5 | AK22: =COUNTIF($B22:$AF22,"B") | AL22: =COUNTIF($B22:$AF22,"J") | AM22: =COUNTIF($B22:$AF22,"T")
AH23: =SUM(AH11:AH22) | AI23: =SUM(AI11:AI22) | AJ23: =SUM(AJ11:AJ22) | AK23: =SUM(AK11:AK22) | AL23: =SUM(AL11:AL22) | AM23: =SUM(AM11:AM22)

Sheet EMPLOYEE5
A1: 2026 Time Off Calendar
A2: EMPLOYEE5
D4: 2026 | F4: Used/ Planned | H4: Balance | J4: Rollover
A5: PTO | F5: =AI23 | H5: =D5-F5 | M5: P | N5: PTO | S5: H | T5: Holiday | Z5: Sat/Sun
A6: Banked PTO | F6: =AJ23 | H6: =D6-F6 | J6: =IF(H5>10,IF(H6+10>20,20,H6+10),IF(H6+H5>20,20,H6+H5)) | M6: PH | N6: 1/2 PTO | S6: B | T6: Bereavement | Y6: R | Z6: Remote
A7: Holiday | D7: 10 | F7: =AH23 | H7: =D7-F7 | M7: PB | N7: Banked PTO | S7: J | T7: Jury Duty
M8: PBH | N8: 1/2 Banked PTO | S8: T | T8: Training
AH9: Total Used/Planned
B10: 1 | C10: 2 | D10: 3 | E10: 4 | F10: 5 | G10: 6 | H10: 7 | I10: 8 | J10: 9 | K10: 10 | L10: 11 | M10: 12 | N10: 13 | O10: 14 | P10: 15 | Q10: 16 | R10: 17 | S10: 18 | T10: 19 | U10: 20 | V10: 21 | W10: 22 | X10: 23 | Y10: 24 | Z10: 25 | AA10: 26 | AB10: 27 | AC10: 28 | AD10: 29 | AE10: 30 | AF10: 31 | AH10: H | AI10: P | AJ10: PB | AK10: B | AL10: J | AM10: T
A11: JAN | B11: H | AH11: =COUNTIF($B11:$AF11,"H") | AI11: =COUNTIF($B11:$AF11,"P")+COUNTIF($B11:$AF11,"PH")*0.5 | AJ11: =COUNTIF($B11:$AF11,"PB")+COUNTIF($B11:$AF11,"PBH")*0.5 | AK11: =COUNTIF($B11:$AF11,"B") | AL11: =COUNTIF($B11:$AF11,"J") | AM11: =COUNTIF($B11:$AF11,"T")
A12: FEB | AH12: =COUNTIF($B12:$AF12,"H") | AI12: =COUNTIF($B12:$AF12,"P")+COUNTIF($B12:$AF12,"PH")*0.5 | AJ12: =COUNTIF($B12:$AF12,"PB")+COUNTIF($B12:$AF12,"PBH")*0.5 | AK12: =COUNTIF($B12:$AF12,"B") | AL12: =COUNTIF($B12:$AF12,"J") | AM12: =COUNTIF($B12:$AF12,"T")
A13: MAR | AH13: =COUNTIF($B13:$AF13,"H") | AI13: =COUNTIF($B13:$AF13,"P")+COUNTIF($B13:$AF13,"PH")*0.5 | AJ13: =COUNTIF($B13:$AF13,"PB")+COUNTIF($B13:$AF13,"PBH")*0.5 | AK13: =COUNTIF($B13:$AF13,"B") | AL13: =COUNTIF($B13:$AF13,"J") | AM13: =COUNTIF($B13:$AF13,"T")
A14: APR | AH14: =COUNTIF($B14:$AF14,"H") | AI14: =COUNTIF($B14:$AF14,"P")+COUNTIF($B14:$AF14,"PH")*0.5 | AJ14: =COUNTIF($B14:$AF14,"PB")+COUNTIF($B14:$AF14,"PBH")*0.5 | AK14: =COUNTIF($B14:$AF14,"B") | AL14: =COUNTIF($B14:$AF14,"J") | AM14: =COUNTIF($B14:$AF14,"T")
A15: MAY | Z15: H | AH15: =COUNTIF($B15:$AF15,"H") | AI15: =COUNTIF($B15:$AF15,"P")+COUNTIF($B15:$AF15,"PH")*0.5 | AJ15: =COUNTIF($B15:$AF15,"PB")+COUNTIF($B15:$AF15,"PBH")*0.5 | AK15: =COUNTIF($B15:$AF15,"B") | AL15: =COUNTIF($B15:$AF15,"J") | AM15: =COUNTIF($B15:$AF15,"T")
A16: JUN | E16: H | AH16: =COUNTIF($B16:$AF16,"H") | AI16: =COUNTIF($B16:$AF16,"P")+COUNTIF($B16:$AF16,"PH")*0.5 | AJ16: =COUNTIF($B16:$AF16,"PB")+COUNTIF($B16:$AF16,"PBH")*0.5 | AK16: =COUNTIF($B16:$AF16,"B") | AL16: =COUNTIF($B16:$AF16,"J") | AM16: =COUNTIF($B16:$AF16,"T")
A17: JUL | AH17: =COUNTIF($B17:$AF17,"H") | AI17: =COUNTIF($B17:$AF17,"P")+COUNTIF($B17:$AF17,"PH")*0.5 | AJ17: =COUNTIF($B17:$AF17,"PB")+COUNTIF($B17:$AF17,"PBH")*0.5 | AK17: =COUNTIF($B17:$AF17,"B") | AL17: =COUNTIF($B17:$AF17,"J") | AM17: =COUNTIF($B17:$AF17,"T")
A18: AUG | AH18: =COUNTIF($B18:$AF18,"H") | AI18: =COUNTIF($B18:$AF18,"P")+COUNTIF($B18:$AF18,"PH")*0.5 | AJ18: =COUNTIF($B18:$AF18,"PB")+COUNTIF($B18:$AF18,"PBH")*0.5 | AK18: =COUNTIF($B18:$AF18,"B") | AL18: =COUNTIF($B18:$AF18,"J") | AM18: =COUNTIF($B18:$AF18,"T")
A19: SEP | H19: H | AH19: =COUNTIF($B19:$AF19,"H") | AI19: =COUNTIF($B19:$AF19,"P")+COUNTIF($B19:$AF19,"PH")*0.5 | AJ19: =COUNTIF($B19:$AF19,"PB")+COUNTIF($B19:$AF19,"PBH")*0.5 | AK19: =COUNTIF($B19:$AF19,"B") | AL19: =COUNTIF($B19:$AF19,"J") | AM19: =COUNTIF($B19:$AF19,"T")
A20: OCT | AH20: =COUNTIF($B20:$AF20,"H") | AI20: =COUNTIF($B20:$AF20,"P")+COUNTIF($B20:$AF20,"PH")*0.5 | AJ20: =COUNTIF($B20:$AF20,"PB")+COUNTIF($B20:$AF20,"PBH")*0.5 | AK20: =COUNTIF($B20:$AF20,"B") | AL20: =COUNTIF($B20:$AF20,"J") | AM20: =COUNTIF($B20:$AF20,"T")
A21: NOV | AA21: H | AH21: =COUNTIF($B21:$AF21,"H") | AI21: =COUNTIF($B21:$AF21,"P")+COUNTIF($B21:$AF21,"PH")*0.5 | AJ21: =COUNTIF($B21:$AF21,"PB")+COUNTIF($B21:$AF21,"PBH")*0.5 | AK21: =COUNTIF($B21:$AF21,"B") | AL21: =COUNTIF($B21:$AF21,"J") | AM21: =COUNTIF($B21:$AF21,"T")
A22: DEC | Z22: H | AH22: =COUNTIF($B22:$AF22,"H") | AI22: =COUNTIF($B22:$AF22,"P")+COUNTIF($B22:$AF22,"PH")*0.5 | AJ22: =COUNTIF($B22:$AF22,"PB")+COUNTIF($B22:$AF22,"PBH")*0.5 | AK22: =COUNTIF($B22:$AF22,"B") | AL22: =COUNTIF($B22:$AF22,"J") | AM22: =COUNTIF($B22:$AF22,"T")
AH23: =SUM(AH11:AH22) | AI23: =SUM(AI11:AI22) | AJ23: =SUM(AJ11:AJ22) | AK23: =SUM(AK11:AK22) | AL23: =SUM(AL11:AL22) | AM23: =SUM(AM11:AM22)

Sheet EMPLOYEE6
A1: 2026 Time Off Calendar
A2: EMPLOYEE6
D4: 2026 | F4: Used/ Planned | H4: Balance | J4: Rollover
A5: PTO | F5: =AI23 | H5: =D5-F5 | M5: P | N5: PTO | S5: H | T5: Holiday | Z5: Sat/Sun
A6: Banked PTO | F6: =AJ23 | H6: =D6-F6 | J6: =IF(H5>10,IF(H6+10>20,20,H6+10),IF(H6+H5>20,20,H6+H5)) | M6: PH | N6: 1/2 PTO | S6: B | T6: Bereavement | Y6: R | Z6: Remote
A7: Holiday | D7: 10 | F7: =AH23 | H7: =D7-F7 | M7: PB | N7: Banked PTO | S7: J | T7: Jury Duty
M8: PBH | N8: 1/2 Banked PTO | S8: T | T8: Training
AH9: Total Used/Planned
B10: 1 | C10: 2 | D10: 3 | E10: 4 | F10: 5 | G10: 6 | H10: 7 | I10: 8 | J10: 9 | K10: 10 | L10: 11 | M10: 12 | N10: 13 | O10: 14 | P10: 15 | Q10: 16 | R10: 17 | S10: 18 | T10: 19 | U10: 20 | V10: 21 | W10: 22 | X10: 23 | Y10: 24 | Z10: 25 | AA10: 26 | AB10: 27 | AC10: 28 | AD10: 29 | AE10: 30 | AF10: 31 | AH10: H | AI10: P | AJ10: PB | AK10: B | AL10: J | AM10: T
A11: JAN | B11: H | AH11: =COUNTIF($B11:$AF11,"H") | AI11: =COUNTIF($B11:$AF11,"P")+COUNTIF($B11:$AF11,"PH")*0.5 | AJ11: =COUNTIF($B11:$AF11,"PB")+COUNTIF($B11:$AF11,"PBH")*0.5 | AK11: =COUNTIF($B11:$AF11,"B") | AL11: =COUNTIF($B11:$AF11,"J") | AM11: =COUNTIF($B11:$AF11,"T")
A12: FEB | AH12: =COUNTIF($B12:$AF12,"H") | AI12: =COUNTIF($B12:$AF12,"P")+COUNTIF($B12:$AF12,"PH")*0.5 | AJ12: =COUNTIF($B12:$AF12,"PB")+COUNTIF($B12:$AF12,"PBH")*0.5 | AK12: =COUNTIF($B12:$AF12,"B") | AL12: =COUNTIF($B12:$AF12,"J") | AM12: =COUNTIF($B12:$AF12,"T")
A13: MAR | AH13: =COUNTIF($B13:$AF13,"H") | AI13: =COUNTIF($B13:$AF13,"P")+COUNTIF($B13:$AF13,"PH")*0.5 | AJ13: =COUNTIF($B13:$AF13,"PB")+COUNTIF($B13:$AF13,"PBH")*0.5 | AK13: =COUNTIF($B13:$AF13,"B") | AL13: =COUNTIF($B13:$AF13,"J") | AM13: =COUNTIF($B13:$AF13,"T")
A14: APR | AH14: =COUNTIF($B14:$AF14,"H") | AI14: =COUNTIF($B14:$AF14,"P")+COUNTIF($B14:$AF14,"PH")*0.5 | AJ14: =COUNTIF($B14:$AF14,"PB")+COUNTIF($B14:$AF14,"PBH")*0.5 | AK14: =COUNTIF($B14:$AF14,"B") | AL14: =COUNTIF($B14:$AF14,"J") | AM14: =COUNTIF($B14:$AF14,"T")
A15: MAY | Z15: H | AH15: =COUNTIF($B15:$AF15,"H") | AI15: =COUNTIF($B15:$AF15,"P")+COUNTIF($B15:$AF15,"PH")*0.5 | AJ15: =COUNTIF($B15:$AF15,"PB")+COUNTIF($B15:$AF15,"PBH")*0.5 | AK15: =COUNTIF($B15:$AF15,"B") | AL15: =COUNTIF($B15:$AF15,"J") | AM15: =COUNTIF($B15:$AF15,"T")
A16: JUN | E16: H | AH16: =COUNTIF($B16:$AF16,"H") | AI16: =COUNTIF($B16:$AF16,"P")+COUNTIF($B16:$AF16,"PH")*0.5 | AJ16: =COUNTIF($B16:$AF16,"PB")+COUNTIF($B16:$AF16,"PBH")*0.5 | AK16: =COUNTIF($B16:$AF16,"B") | AL16: =COUNTIF($B16:$AF16,"J") | AM16: =COUNTIF($B16:$AF16,"T")
A17: JUL | AH17: =COUNTIF($B17:$AF17,"H") | AI17: =COUNTIF($B17:$AF17,"P")+COUNTIF($B17:$AF17,"PH")*0.5 | AJ17: =COUNTIF($B17:$AF17,"PB")+COUNTIF($B17:$AF17,"PBH")*0.5 | AK17: =COUNTIF($B17:$AF17,"B") | AL17: =COUNTIF($B17:$AF17,"J") | AM17: =COUNTIF($B17:$AF17,"T")
A18: AUG | AH18: =COUNTIF($B18:$AF18,"H") | AI18: =COUNTIF($B18:$AF18,"P")+COUNTIF($B18:$AF18,"PH")*0.5 | AJ18: =COUNTIF($B18:$AF18,"PB")+COUNTIF($B18:$AF18,"PBH")*0.5 | AK18: =COUNTIF($B18:$AF18,"B") | AL18: =COUNTIF($B18:$AF18,"J") | AM18: =COUNTIF($B18:$AF18,"T")
A19: SEP | H19: H | AH19: =COUNTIF($B19:$AF19,"H") | AI19: =COUNTIF($B19:$AF19,"P")+COUNTIF($B19:$AF19,"PH")*0.5 | AJ19: =COUNTIF($B19:$AF19,"PB")+COUNTIF($B19:$AF19,"PBH")*0.5 | AK19: =COUNTIF($B19:$AF19,"B") | AL19: =COUNTIF($B19:$AF19,"J") | AM19: =COUNTIF($B19:$AF19,"T")
A20: OCT | AH20: =COUNTIF($B20:$AF20,"H") | AI20: =COUNTIF($B20:$AF20,"P")+COUNTIF($B20:$AF20,"PH")*0.5 | AJ20: =COUNTIF($B20:$AF20,"PB")+COUNTIF($B20:$AF20,"PBH")*0.5 | AK20: =COUNTIF($B20:$AF20,"B") | AL20: =COUNTIF($B20:$AF20,"J") | AM20: =COUNTIF($B20:$AF20,"T")
A21: NOV | AA21: H | AH21: =COUNTIF($B21:$AF21,"H") | AI21: =COUNTIF($B21:$AF21,"P")+COUNTIF($B21:$AF21,"PH")*0.5 | AJ21: =COUNTIF($B21:$AF21,"PB")+COUNTIF($B21:$AF21,"PBH")*0.5 | AK21: =COUNTIF($B21:$AF21,"B") | AL21: =COUNTIF($B21:$AF21,"J") | AM21: =COUNTIF($B21:$AF21,"T")
A22: DEC | Z22: H | AH22: =COUNTIF($B22:$AF22,"H") | AI22: =COUNTIF($B22:$AF22,"P")+COUNTIF($B22:$AF22,"PH")*0.5 | AJ22: =COUNTIF($B22:$AF22,"PB")+COUNTIF($B22:$AF22,"PBH")*0.5 | AK22: =COUNTIF($B22:$AF22,"B") | AL22: =COUNTIF($B22:$AF22,"J") | AM22: =COUNTIF($B22:$AF22,"T")
AH23: =SUM(AH11:AH22) | AI23: =SUM(AI11:AI22) | AJ23: =SUM(AJ11:AJ22) | AK23: =SUM(AK11:AK22) | AL23: =SUM(AL11:AL22) | AM23: =SUM(AM11:AM22)

Sheet EMPLOYEE7
A1: 2026 Time Off Calendar
A2: EMPLOYEE7
D4: 2026 | F4: Used/ Planned | H4: Balance | J4: Rollover
A5: PTO | F5: =AI23 | H5: =D5-F5 | M5: P | N5: PTO | S5: H | T5: Holiday | Z5: Sat/Sun
A6: Banked PTO | F6: =AJ23 | H6: =D6-F6 | J6: =IF(H5>10,IF(H6+10>20,20,H6+10),IF(H6+H5>20,20,H6+H5)) | M6: PH | N6: 1/2 PTO | S6: B | T6: Bereavement | Y6: R | Z6: Remote
A7: Holiday | D7: 10 | F7: =AH23 | H7: =D7-F7 | M7: PB | N7: Banked PTO | S7: J | T7: Jury Duty
M8: PBH | N8: 1/2 Banked PTO | S8: T | T8: Training
AH9: Total Used/Planned
B10: 1 | C10: 2 | D10: 3 | E10: 4 | F10: 5 | G10: 6 | H10: 7 | I10: 8 | J10: 9 | K10: 10 | L10: 11 | M10: 12 | N10: 13 | O10: 14 | P10: 15 | Q10: 16 | R10: 17 | S10: 18 | T10: 19 | U10: 20 | V10: 21 | W10: 22 | X10: 23 | Y10: 24 | Z10: 25 | AA10: 26 | AB10: 27 | AC10: 28 | AD10: 29 | AE10: 30 | AF10: 31 | AH10: H | AI10: P | AJ10: PB | AK10: B | AL10: J | AM10: T
A11: JAN | B11: H | AH11: =COUNTIF($B11:$AF11,"H") | AI11: =COUNTIF($B11:$AF11,"P")+COUNTIF($B11:$AF11,"PH")*0.5 | AJ11: =COUNTIF($B11:$AF11,"PB")+COUNTIF($B11:$AF11,"PBH")*0.5 | AK11: =COUNTIF($B11:$AF11,"B") | AL11: =COUNTIF($B11:$AF11,"J") | AM11: =COUNTIF($B11:$AF11,"T")
A12: FEB | AH12: =COUNTIF($B12:$AF12,"H") | AI12: =COUNTIF($B12:$AF12,"P")+COUNTIF($B12:$AF12,"PH")*0.5 | AJ12: =COUNTIF($B12:$AF12,"PB")+COUNTIF($B12:$AF12,"PBH")*0.5 | AK12: =COUNTIF($B12:$AF12,"B") | AL12: =COUNTIF($B12:$AF12,"J") | AM12: =COUNTIF($B12:$AF12,"T")
A13: MAR | AH13: =COUNTIF($B13:$AF13,"H") | AI13: =COUNTIF($B13:$AF13,"P")+COUNTIF($B13:$AF13,"PH")*0.5 | AJ13: =COUNTIF($B13:$AF13,"PB")+COUNTIF($B13:$AF13,"PBH")*0.5 | AK13: =COUNTIF($B13:$AF13,"B") | AL13: =COUNTIF($B13:$AF13,"J") | AM13: =COUNTIF($B13:$AF13,"T")
A14: APR | AH14: =COUNTIF($B14:$AF14,"H") | AI14: =COUNTIF($B14:$AF14,"P")+COUNTIF($B14:$AF14,"PH")*0.5 | AJ14: =COUNTIF($B14:$AF14,"PB")+COUNTIF($B14:$AF14,"PBH")*0.5 | AK14: =COUNTIF($B14:$AF14,"B") | AL14: =COUNTIF($B14:$AF14,"J") | AM14: =COUNTIF($B14:$AF14,"T")
A15: MAY | Z15: H | AH15: =COUNTIF($B15:$AF15,"H") | AI15: =COUNTIF($B15:$AF15,"P")+COUNTIF($B15:$AF15,"PH")*0.5 | AJ15: =COUNTIF($B15:$AF15,"PB")+COUNTIF($B15:$AF15,"PBH")*0.5 | AK15: =COUNTIF($B15:$AF15,"B") | AL15: =COUNTIF($B15:$AF15,"J") | AM15: =COUNTIF($B15:$AF15,"T")
A16: JUN | E16: H | AH16: =COUNTIF($B16:$AF16,"H") | AI16: =COUNTIF($B16:$AF16,"P")+COUNTIF($B16:$AF16,"PH")*0.5 | AJ16: =COUNTIF($B16:$AF16,"PB")+COUNTIF($B16:$AF16,"PBH")*0.5 | AK16: =COUNTIF($B16:$AF16,"B") | AL16: =COUNTIF($B16:$AF16,"J") | AM16: =COUNTIF($B16:$AF16,"T")
A17: JUL | AH17: =COUNTIF($B17:$AF17,"H") | AI17: =COUNTIF($B17:$AF17,"P")+COUNTIF($B17:$AF17,"PH")*0.5 | AJ17: =COUNTIF($B17:$AF17,"PB")+COUNTIF($B17:$AF17,"PBH")*0.5 | AK17: =COUNTIF($B17:$AF17,"B") | AL17: =COUNTIF($B17:$AF17,"J") | AM17: =COUNTIF($B17:$AF17,"T")
A18: AUG | AH18: =COUNTIF($B18:$AF18,"H") | AI18: =COUNTIF($B18:$AF18,"P")+COUNTIF($B18:$AF18,"PH")*0.5 | AJ18: =COUNTIF($B18:$AF18,"PB")+COUNTIF($B18:$AF18,"PBH")*0.5 | AK18: =COUNTIF($B18:$AF18,"B") | AL18: =COUNTIF($B18:$AF18,"J") | AM18: =COUNTIF($B18:$AF18,"T")
A19: SEP | H19: H | AH19: =COUNTIF($B19:$AF19,"H") | AI19: =COUNTIF($B19:$AF19,"P")+COUNTIF($B19:$AF19,"PH")*0.5 | AJ19: =COUNTIF($B19:$AF19,"PB")+COUNTIF($B19:$AF19,"PBH")*0.5 | AK19: =COUNTIF($B19:$AF19,"B") | AL19: =COUNTIF($B19:$AF19,"J") | AM19: =COUNTIF($B19:$AF19,"T")
A20: OCT | AH20: =COUNTIF($B20:$AF20,"H") | AI20: =COUNTIF($B20:$AF20,"P")+COUNTIF($B20:$AF20,"PH")*0.5 | AJ20: =COUNTIF($B20:$AF20,"PB")+COUNTIF($B20:$AF20,"PBH")*0.5 | AK20: =COUNTIF($B20:$AF20,"B") | AL20: =COUNTIF($B20:$AF20,"J") | AM20: =COUNTIF($B20:$AF20,"T")
A21: NOV | AA21: H | AH21: =COUNTIF($B21:$AF21,"H") | AI21: =COUNTIF($B21:$AF21,"P")+COUNTIF($B21:$AF21,"PH")*0.5 | AJ21: =COUNTIF($B21:$AF21,"PB")+COUNTIF($B21:$AF21,"PBH")*0.5 | AK21: =COUNTIF($B21:$AF21,"B") | AL21: =COUNTIF($B21:$AF21,"J") | AM21: =COUNTIF($B21:$AF21,"T")
A22: DEC | Z22: H | AH22: =COUNTIF($B22:$AF22,"H") | AI22: =COUNTIF($B22:$AF22,"P")+COUNTIF($B22:$AF22,"PH")*0.5 | AJ22: =COUNTIF($B22:$AF22,"PB")+COUNTIF($B22:$AF22,"PBH")*0.5 | AK22: =COUNTIF($B22:$AF22,"B") | AL22: =COUNTIF($B22:$AF22,"J") | AM22: =COUNTIF($B22:$AF22,"T")
AH23: =SUM(AH11:AH22) | AI23: =SUM(AI11:AI22) | AJ23: =SUM(AJ11:AJ22) | AK23: =SUM(AK11:AK22) | AL23: =SUM(AL11:AL22) | AM23: =SUM(AM11:AM22)

Sheet EMPLOYEE8
A1: 2026 Time Off Calendar
A2: EMPLOYEE8
D4: 2026 | F4: Used/ Planned | H4: Balance | J4: Rollover
A5: PTO | F5: =AI23 | H5: =D5-F5 | M5: P | N5: PTO | S5: H | T5: Holiday | Z5: Sat/Sun
A6: Banked PTO | F6: =AJ23 | H6: =D6-F6 | J6: =IF(H5>10,IF(H6+10>20,20,H6+10),IF(H6+H5>20,20,H6+H5)) | M6: PH | N6: 1/2 PTO | S6: B | T6: Bereavement | Y6: R | Z6: Remote
A7: Holiday | D7: 10 | F7: =AH23 | H7: =D7-F7 | M7: PB | N7: Banked PTO | S7: J | T7: Jury Duty
M8: PBH | N8: 1/2 Banked PTO | S8: T | T8: Training
AH9: Total Used/Planned
B10: 1 | C10: 2 | D10: 3 | E10: 4 | F10: 5 | G10: 6 | H10: 7 | I10: 8 | J10: 9 | K10: 10 | L10: 11 | M10: 12 | N10: 13 | O10: 14 | P10: 15 | Q10: 16 | R10: 17 | S10: 18 | T10: 19 | U10: 20 | V10: 21 | W10: 22 | X10: 23 | Y10: 24 | Z10: 25 | AA10: 26 | AB10: 27 | AC10: 28 | AD10: 29 | AE10: 30 | AF10: 31 | AH10: H | AI10: P | AJ10: PB | AK10: B | AL10: J | AM10: T
A11: JAN | B11: H | AH11: =COUNTIF($B11:$AF11,"H") | AI11: =COUNTIF($B11:$AF11,"P")+COUNTIF($B11:$AF11,"PH")*0.5 | AJ11: =COUNTIF($B11:$AF11,"PB")+COUNTIF($B11:$AF11,"PBH")*0.5 | AK11: =COUNTIF($B11:$AF11,"B") | AL11: =COUNTIF($B11:$AF11,"J") | AM11: =COUNTIF($B11:$AF11,"T")
A12: FEB | AH12: =COUNTIF($B12:$AF12,"H") | AI12: =COUNTIF($B12:$AF12,"P")+COUNTIF($B12:$AF12,"PH")*0.5 | AJ12: =COUNTIF($B12:$AF12,"PB")+COUNTIF($B12:$AF12,"PBH")*0.5 | AK12: =COUNTIF($B12:$AF12,"B") | AL12: =COUNTIF($B12:$AF12,"J") | AM12: =COUNTIF($B12:$AF12,"T")
A13: MAR | AH13: =COUNTIF($B13:$AF13,"H") | AI13: =COUNTIF($B13:$AF13,"P")+COUNTIF($B13:$AF13,"PH")*0.5 | AJ13: =COUNTIF($B13:$AF13,"PB")+COUNTIF($B13:$AF13,"PBH")*0.5 | AK13: =COUNTIF($B13:$AF13,"B") | AL13: =COUNTIF($B13:$AF13,"J") | AM13: =COUNTIF($B13:$AF13,"T")
A14: APR | AH14: =COUNTIF($B14:$AF14,"H") | AI14: =COUNTIF($B14:$AF14,"P")+COUNTIF($B14:$AF14,"PH")*0.5 | AJ14: =COUNTIF($B14:$AF14,"PB")+COUNTIF($B14:$AF14,"PBH")*0.5 | AK14: =COUNTIF($B14:$AF14,"B") | AL14: =COUNTIF($B14:$AF14,"J") | AM14: =COUNTIF($B14:$AF14,"T")
A15: MAY | Z15: H | AH15: =COUNTIF($B15:$AF15,"H") | AI15: =COUNTIF($B15:$AF15,"P")+COUNTIF($B15:$AF15,"PH")*0.5 | AJ15: =COUNTIF($B15:$AF15,"PB")+COUNTIF($B15:$AF15,"PBH")*0.5 | AK15: =COUNTIF($B15:$AF15,"B") | AL15: =COUNTIF($B15:$AF15,"J") | AM15: =COUNTIF($B15:$AF15,"T")
A16: JUN | E16: H | AH16: =COUNTIF($B16:$AF16,"H") | AI16: =COUNTIF($B16:$AF16,"P")+COUNTIF($B16:$AF16,"PH")*0.5 | AJ16: =COUNTIF($B16:$AF16,"PB")+COUNTIF($B16:$AF16,"PBH")*0.5 | AK16: =COUNTIF($B16:$AF16,"B") | AL16: =COUNTIF($B16:$AF16,"J") | AM16: =COUNTIF($B16:$AF16,"T")
A17: JUL | AH17: =COUNTIF($B17:$AF17,"H") | AI17: =COUNTIF($B17:$AF17,"P")+COUNTIF($B17:$AF17,"PH")*0.5 | AJ17: =COUNTIF($B17:$AF17,"PB")+COUNTIF($B17:$AF17,"PBH")*0.5 | AK17: =COUNTIF($B17:$AF17,"B") | AL17: =COUNTIF($B17:$AF17,"J") | AM17: =COUNTIF($B17:$AF17,"T")
A18: AUG | AH18: =COUNTIF($B18:$AF18,"H") | AI18: =COUNTIF($B18:$AF18,"P")+COUNTIF($B18:$AF18,"PH")*0.5 | AJ18: =COUNTIF($B18:$AF18,"PB")+COUNTIF($B18:$AF18,"PBH")*0.5 | AK18: =COUNTIF($B18:$AF18,"B") | AL18: =COUNTIF($B18:$AF18,"J") | AM18: =COUNTIF($B18:$AF18,"T")
A19: SEP | H19: H | AH19: =COUNTIF($B19:$AF19,"H") | AI19: =COUNTIF($B19:$AF19,"P")+COUNTIF($B19:$AF19,"PH")*0.5 | AJ19: =COUNTIF($B19:$AF19,"PB")+COUNTIF($B19:$AF19,"PBH")*0.5 | AK19: =COUNTIF($B19:$AF19,"B") | AL19: =COUNTIF($B19:$AF19,"J") | AM19: =COUNTIF($B19:$AF19,"T")
A20: OCT | AH20: =COUNTIF($B20:$AF20,"H") | AI20: =COUNTIF($B20:$AF20,"P")+COUNTIF($B20:$AF20,"PH")*0.5 | AJ20: =COUNTIF($B20:$AF20,"PB")+COUNTIF($B20:$AF20,"PBH")*0.5 | AK20: =COUNTIF($B20:$AF20,"B") | AL20: =COUNTIF($B20:$AF20,"J") | AM20: =COUNTIF($B20:$AF20,"T")
A21: NOV | AA21: H | AH21: =COUNTIF($B21:$AF21,"H") | AI21: =COUNTIF($B21:$AF21,"P")+COUNTIF($B21:$AF21,"PH")*0.5 | AJ21: =COUNTIF($B21:$AF21,"PB")+COUNTIF($B21:$AF21,"PBH")*0.5 | AK21: =COUNTIF($B21:$AF21,"B") | AL21: =COUNTIF($B21:$AF21,"J") | AM21: =COUNTIF($B21:$AF21,"T")
A22: DEC | Z22: H | AH22: =COUNTIF($B22:$AF22,"H") | AI22: =COUNTIF($B22:$AF22,"P")+COUNTIF($B22:$AF22,"PH")*0.5 | AJ22: =COUNTIF($B22:$AF22,"PB")+COUNTIF($B22:$AF22,"PBH")*0.5 | AK22: =COUNTIF($B22:$AF22,"B") | AL22: =COUNTIF($B22:$AF22,"J") | AM22: =COUNTIF($B22:$AF22,"T")
AH23: =SUM(AH11:AH22) | AI23: =SUM(AI11:AI22) | AJ23: =SUM(AJ11:AJ22) | AK23: =SUM(AK11:AK22) | AL23: =SUM(AL11:AL22) | AM23: =SUM(AM11:AM22)

Sheet EMPLOYEE9
A1: 2026 Time Off Calendar
A2: EMPLOYEE9
D4: 2026 | F4: Used/ Planned | H4: Balance | J4: Rollover
A5: PTO | F5: =AI23 | H5: =D5-F5 | M5: P | N5: PTO | S5: H | T5: Holiday | Z5: Sat/Sun
A6: Banked PTO | F6: =AJ23 | H6: =D6-F6 | J6: =IF(H5>10,IF(H6+10>20,20,H6+10),IF(H6+H5>20,20,H6+H5)) | M6: PH | N6: 1/2 PTO | S6: B | T6: Bereavement | Y6: R | Z6: Remote
A7: Holiday | D7: 10 | F7: =AH23 | H7: =D7-F7 | M7: PB | N7: Banked PTO | S7: J | T7: Jury Duty
M8: PBH | N8: 1/2 Banked PTO | S8: T | T8: Training
AH9: Total Used/Planned
B10: 1 | C10: 2 | D10: 3 | E10: 4 | F10: 5 | G10: 6 | H10: 7 | I10: 8 | J10: 9 | K10: 10 | L10: 11 | M10: 12 | N10: 13 | O10: 14 | P10: 15 | Q10: 16 | R10: 17 | S10: 18 | T10: 19 | U10: 20 | V10: 21 | W10: 22 | X10: 23 | Y10: 24 | Z10: 25 | AA10: 26 | AB10: 27 | AC10: 28 | AD10: 29 | AE10: 30 | AF10: 31 | AH10: H | AI10: P | AJ10: PB | AK10: B | AL10: J | AM10: T
A11: JAN | B11: H | AH11: =COUNTIF($B11:$AF11,"H") | AI11: =COUNTIF($B11:$AF11,"P")+COUNTIF($B11:$AF11,"PH")*0.5 | AJ11: =COUNTIF($B11:$AF11,"PB")+COUNTIF($B11:$AF11,"PBH")*0.5 | AK11: =COUNTIF($B11:$AF11,"B") | AL11: =COUNTIF($B11:$AF11,"J") | AM11: =COUNTIF($B11:$AF11,"T")
A12: FEB | AH12: =COUNTIF($B12:$AF12,"H") | AI12: =COUNTIF($B12:$AF12,"P")+COUNTIF($B12:$AF12,"PH")*0.5 | AJ12: =COUNTIF($B12:$AF12,"PB")+COUNTIF($B12:$AF12,"PBH")*0.5 | AK12: =COUNTIF($B12:$AF12,"B") | AL12: =COUNTIF($B12:$AF12,"J") | AM12: =COUNTIF($B12:$AF12,"T")
A13: MAR | AH13: =COUNTIF($B13:$AF13,"H") | AI13: =COUNTIF($B13:$AF13,"P")+COUNTIF($B13:$AF13,"PH")*0.5 | AJ13: =COUNTIF($B13:$AF13,"PB")+COUNTIF($B13:$AF13,"PBH")*0.5 | AK13: =COUNTIF($B13:$AF13,"B") | AL13: =COUNTIF($B13:$AF13,"J") | AM13: =COUNTIF($B13:$AF13,"T")
A14: APR | AH14: =COUNTIF($B14:$AF14,"H") | AI14: =COUNTIF($B14:$AF14,"P")+COUNTIF($B14:$AF14,"PH")*0.5 | AJ14: =COUNTIF($B14:$AF14,"PB")+COUNTIF($B14:$AF14,"PBH")*0.5 | AK14: =COUNTIF($B14:$AF14,"B") | AL14: =COUNTIF($B14:$AF14,"J") | AM14: =COUNTIF($B14:$AF14,"T")
A15: MAY | Z15: H | AH15: =COUNTIF($B15:$AF15,"H") | AI15: =COUNTIF($B15:$AF15,"P")+COUNTIF($B15:$AF15,"PH")*0.5 | AJ15: =COUNTIF($B15:$AF15,"PB")+COUNTIF($B15:$AF15,"PBH")*0.5 | AK15: =COUNTIF($B15:$AF15,"B") | AL15: =COUNTIF($B15:$AF15,"J") | AM15: =COUNTIF($B15:$AF15,"T")
A16: JUN | E16: H | AH16: =COUNTIF($B16:$AF16,"H") | AI16: =COUNTIF($B16:$AF16,"P")+COUNTIF($B16:$AF16,"PH")*0.5 | AJ16: =COUNTIF($B16:$AF16,"PB")+COUNTIF($B16:$AF16,"PBH")*0.5 | AK16: =COUNTIF($B16:$AF16,"B") | AL16: =COUNTIF($B16:$AF16,"J") | AM16: =COUNTIF($B16:$AF16,"T")
A17: JUL | AH17: =COUNTIF($B17:$AF17,"H") | AI17: =COUNTIF($B17:$AF17,"P")+COUNTIF($B17:$AF17,"PH")*0.5 | AJ17: =COUNTIF($B17:$AF17,"PB")+COUNTIF($B17:$AF17,"PBH")*0.5 | AK17: =COUNTIF($B17:$AF17,"B") | AL17: =COUNTIF($B17:$AF17,"J") | AM17: =COUNTIF($B17:$AF17,"T")
A18: AUG | AH18: =COUNTIF($B18:$AF18,"H") | AI18: =COUNTIF($B18:$AF18,"P")+COUNTIF($B18:$AF18,"PH")*0.5 | AJ18: =COUNTIF($B18:$AF18,"PB")+COUNTIF($B18:$AF18,"PBH")*0.5 | AK18: =COUNTIF($B18:$AF18,"B") | AL18: =COUNTIF($B18:$AF18,"J") | AM18: =COUNTIF($B18:$AF18,"T")
A19: SEP | H19: H | AH19: =COUNTIF($B19:$AF19,"H") | AI19: =COUNTIF($B19:$AF19,"P")+COUNTIF($B19:$AF19,"PH")*0.5 | AJ19: =COUNTIF($B19:$AF19,"PB")+COUNTIF($B19:$AF19,"PBH")*0.5 | AK19: =COUNTIF($B19:$AF19,"B") | AL19: =COUNTIF($B19:$AF19,"J") | AM19: =COUNTIF($B19:$AF19,"T")
A20: OCT | AH20: =COUNTIF($B20:$AF20,"H") | AI20: =COUNTIF($B20:$AF20,"P")+COUNTIF($B20:$AF20,"PH")*0.5 | AJ20: =COUNTIF($B20:$AF20,"PB")+COUNTIF($B20:$AF20,"PBH")*0.5 | AK20: =COUNTIF($B20:$AF20,"B") | AL20: =COUNTIF($B20:$AF20,"J") | AM20: =COUNTIF($B20:$AF20,"T")
A21: NOV | AA21: H | AH21: =COUNTIF($B21:$AF21,"H") | AI21: =COUNTIF($B21:$AF21,"P")+COUNTIF($B21:$AF21,"PH")*0.5 | AJ21: =COUNTIF($B21:$AF21,"PB")+COUNTIF($B21:$AF21,"PBH")*0.5 | AK21: =COUNTIF($B21:$AF21,"B") | AL21: =COUNTIF($B21:$AF21,"J") | AM21: =COUNTIF($B21:$AF21,"T")
