Workbook

Sheet Start
B2: Helix package quotes
B3: Pick a package, enter the details, download the one-pager as a PDF.
B5: 1 | C5: Quote
C6: Choose the package from the dropdown, then fill in the blue cells. Add-ons are optional.
B8: 2 | C8: One-Pager
C9: This is the PDF. Check it, then File › Download › PDF. Use: Current sheet · Letter · Portrait · Fit to width · Margins: Narrow · uncheck Show gridlines.
B11: 3 | C11: Packages
C12: The package library. Change prices, wording, or add a package here once and every quote uses it. Rows marked PLACEHOLDER need real prices before anything goes out.

Sheet Quote
A1: Quote
A2: Fill in the blue cells. The One-Pager tab updates on its own.
A4: Package | B4: Live Zoom Package
A5: Client | B5: Helix
A6: Event date | B6: =DATE(2026,10,22)
A7: Days | B7: 1
A8: Quote number | B8: 0625
A9: Issued | B9: =DATE(2026,10,28)
A10: Valid until | B10: =B9+30
A11: Tax rate | B11: 0
A12: Contact name | B12: Rick
A13: Contact email | B13: Rick@368eventmanagement.com
A14: Contact phone | B14: (201) 893-5224
A16: Add-ons (optional) | B16: Shown after the package sections. Price is flat, not multiplied by days.
B17: Name | C17: Description | D17: Price
A18: Add-on 1
A19: Add-on 2
A21: Total | B21: ='One-Pager'!B39 | C21: Same number as the One-Pager.

Sheet One-Pager
M1: =COUNTIF(Packages!$E$6:$E$105,Quote!$B$4)
B2: 368 EVENT MANAGEMENT × HELLHOUND AUDIO | G2: ="Prepared for "&Quote!$B$5&" · Quote "&Quote!$B$8 | M2: sections
B4: =UPPER(Quote!$B$5&" · "&TEXT(Quote!$B$6,"mmmm d, yyyy"))
B5: =IFERROR(INDEX(Packages!$B$6:$B$25,MATCH(Quote!$B$4,Packages!$A$6:$A$25,0)),"")
B8: What’s in the package
B10: =IFERROR(IF(1<=$M$1,INDEX(Packages!$F$6:$F$105,MATCH(Quote!$B$4&"|1",Packages!$D$6:$D$105,0)),INDEX(Quote!$B$18:$B$19,1-$M$1)&""),"") | I10: =IFERROR(IF(B10="","",IF(1<=$M$1,INDEX(Packages!$H$6:$H$105,MATCH(Quote!$B$4&"|1",Packages!$D$6:$D$105,0))*Quote!$B$7,INDEX(Quote!$D$18:$D$19,1-$M$1))),"")
B11: =IFERROR(IF(1<=$M$1,INDEX(Packages!$G$6:$G$105,MATCH(Quote!$B$4&"|1",Packages!$D$6:$D$105,0)),INDEX(Quote!$C$18:$C$19,1-$M$1)&""),"")
B13: =IFERROR(IF(2<=$M$1,INDEX(Packages!$F$6:$F$105,MATCH(Quote!$B$4&"|2",Packages!$D$6:$D$105,0)),INDEX(Quote!$B$18:$B$19,2-$M$1)&""),"") | I13: =IFERROR(IF(B13="","",IF(2<=$M$1,INDEX(Packages!$H$6:$H$105,MATCH(Quote!$B$4&"|2",Packages!$D$6:$D$105,0))*Quote!$B$7,INDEX(Quote!$D$18:$D$19,2-$M$1))),"")
B14: =IFERROR(IF(2<=$M$1,INDEX(Packages!$G$6:$G$105,MATCH(Quote!$B$4&"|2",Packages!$D$6:$D$105,0)),INDEX(Quote!$C$18:$C$19,2-$M$1)&""),"")
B16: =IFERROR(IF(3<=$M$1,INDEX(Packages!$F$6:$F$105,MATCH(Quote!$B$4&"|3",Packages!$D$6:$D$105,0)),INDEX(Quote!$B$18:$B$19,3-$M$1)&""),"") | I16: =IFERROR(IF(B16="","",IF(3<=$M$1,INDEX(Packages!$H$6:$H$105,MATCH(Quote!$B$4&"|3",Packages!$D$6:$D$105,0))*Quote!$B$7,INDEX(Quote!$D$18:$D$19,3-$M$1))),"")
B17: =IFERROR(IF(3<=$M$1,INDEX(Packages!$G$6:$G$105,MATCH(Quote!$B$4&"|3",Packages!$D$6:$D$105,0)),INDEX(Quote!$C$18:$C$19,3-$M$1)&""),"")
B19: =IFERROR(IF(4<=$M$1,INDEX(Packages!$F$6:$F$105,MATCH(Quote!$B$4&"|4",Packages!$D$6:$D$105,0)),INDEX(Quote!$B$18:$B$19,4-$M$1)&""),"") | I19: =IFERROR(IF(B19="","",IF(4<=$M$1,INDEX(Packages!$H$6:$H$105,MATCH(Quote!$B$4&"|4",Packages!$D$6:$D$105,0))*Quote!$B$7,INDEX(Quote!$D$18:$D$19,4-$M$1))),"")
B20: =IFERROR(IF(4<=$M$1,INDEX(Packages!$G$6:$G$105,MATCH(Quote!$B$4&"|4",Packages!$D$6:$D$105,0)),INDEX(Quote!$C$18:$C$19,4-$M$1)&""),"")
B22: =IFERROR(IF(5<=$M$1,INDEX(Packages!$F$6:$F$105,MATCH(Quote!$B$4&"|5",Packages!$D$6:$D$105,0)),INDEX(Quote!$B$18:$B$19,5-$M$1)&""),"") | I22: =IFERROR(IF(B22="","",IF(5<=$M$1,INDEX(Packages!$H$6:$H$105,MATCH(Quote!$B$4&"|5",Packages!$D$6:$D$105,0))*Quote!$B$7,INDEX(Quote!$D$18:$D$19,5-$M$1))),"")
B23: =IFERROR(IF(5<=$M$1,INDEX(Packages!$G$6:$G$105,MATCH(Quote!$B$4&"|5",Packages!$D$6:$D$105,0)),INDEX(Quote!$C$18:$C$19,5-$M$1)&""),"")
B26: =IF(COUNTIF(Packages!$K$6:$K$155,Quote!$B$4&"|*")=0,"","Also included")
B28: =IFERROR("✓ "&INDEX(Packages!$M$6:$M$155,MATCH(Quote!$B$4&"|1",Packages!$K$6:$K$155,0)),"") | G28: =IFERROR("✓ "&INDEX(Packages!$M$6:$M$155,MATCH(Quote!$B$4&"|4",Packages!$K$6:$K$155,0)),"")
B29: =IFERROR("✓ "&INDEX(Packages!$M$6:$M$155,MATCH(Quote!$B$4&"|2",Packages!$K$6:$K$155,0)),"") | G29: =IFERROR("✓ "&INDEX(Packages!$M$6:$M$155,MATCH(Quote!$B$4&"|5",Packages!$K$6:$K$155,0)),"")
B30: =IFERROR("✓ "&INDEX(Packages!$M$6:$M$155,MATCH(Quote!$B$4&"|3",Packages!$K$6:$K$155,0)),"") | G30: =IFERROR("✓ "&INDEX(Packages!$M$6:$M$155,MATCH(Quote!$B$4&"|6",Packages!$K$6:$K$155,0)),"")
B38: TOTAL
B39: =SUM(I10,I13,I16,I19,I22)*(1+Quote!$B$11) | G39: =IF(Quote!$B$11>0,"Includes tax ("&TEXT(Quote!$B$11,"0.###%")&")","")
B41: =Quote!$B$12&" · "&Quote!$B$13&" · "&Quote!$B$14
B42: ="Quote "&Quote!$B$8&" · Issued "&TEXT(Quote!$B$9,"mmm d, yyyy")&" · Valid until "&TEXT(Quote!$B$10,"mmm d, yyyy")

Sheet Packages
A1: Packages
A2: Edit prices and wording here. Add a package: add its name and headline on the left, then its sections and bullets using the same name.
A3: Red rows are PLACEHOLDER prices. Replace them before sending a quote for that package.
A5: Package | B5: Headline (two lines) | D5: Key | E5: Package | F5: Section | G5: Description | H5: Price / day | I5: Status | K5: Key | L5: Package | M5: Also included
A6: Live Zoom Package | B6: Your Zoom Call Package | D6: =IF(E6="","",E6&"|"&COUNTIF($E$6:E6,E6)) | E6: Live Zoom Package | F6: Crew | G6: Senior audio technician (A1), video technician (V1) | H6: 1200 | I6: From quote 0625 | K6: =IF(L6="","",L6&"|"&COUNTIF($L$6:L6,L6)) | L6: Live Zoom Package | M6: Joystick camera controller
A7: Cocktail Hour Sound | B7: Your Cocktail Hour Sound | D7: =IF(E7="","",E7&"|"&COUNTIF($E$6:E7,E7)) | E7: Live Zoom Package | F7: Video | G7: BirdDog X5 Ultra PTZ camera, Roland V-02HD MK II mixer, MacBook Air M2 | H7: 850 | I7: From quote 0625 | K7: =IF(L7="","",L7&"|"&COUNTIF($L$6:L7,L7)) | L7: Live Zoom Package | M7: SDI and HDMI cable package
A8: Room Rental | B8: Your Room at Helix | D8: =IF(E8="","",E8&"|"&COUNTIF($E$6:E8,E8)) | E8: Live Zoom Package | F8: Audio | G8: Focusrite Scarlett 2i2, Radial direct boxes, iPad | H8: 600 | I8: From quote 0625 (includes transport) | K8: =IF(L8="","",L8&"|"&COUNTIF($L$6:L8,L8)) | L8: Live Zoom Package | M8: Remote pan, tilt, and zoom
D9: =IF(E9="","",E9&"|"&COUNTIF($E$6:E9,E9)) | E9: Cocktail Hour Sound | F9: Crew | G9: Audio engineer (A1), on site for the event | H9: 600 | I9: PLACEHOLDER | K9: =IF(L9="","",L9&"|"&COUNTIF($L$6:L9,L9)) | L9: Live Zoom Package | M9: 4K camera monitor for the technician
D10: =IF(E10="","",E10&"|"&COUNTIF($E$6:E10,E10)) | E10: Cocktail Hour Sound | F10: Sound system | G10: PA speakers, digital mixer, wireless mics | H10: 750 | I10: PLACEHOLDER | K10: =IF(L10="","",L10&"|"&COUNTIF($L$6:L10,L10)) | L10: Live Zoom Package | M10: PoE+ network switch
D11: =IF(E11="","",E11&"|"&COUNTIF($E$6:E11,E11)) | E11: Cocktail Hour Sound | F11: Band setup | G11: Stage mics, monitors, and direct boxes for the band | H11: 400 | I11: PLACEHOLDER | K11: =IF(L11="","",L11&"|"&COUNTIF($L$6:L11,L11)) | L11: Live Zoom Package | M11: Camera tripods
D12: =IF(E12="","",E12&"|"&COUNTIF($E$6:E12,E12)) | E12: Room Rental | F12: Room | G12: Event space at Helix, 20 French St, New Brunswick | H12: 5000 | I12: PLACEHOLDER | K12: =IF(L12="","",L12&"|"&COUNTIF($L$6:L12,L12)) | L12: Cocktail Hour Sound | M12: Background music playback
D13: =IF(E13="","",E13&"|"&COUNTIF($E$6:E13,E13)) | E13: Room Rental | F13: Presentation AV | G13: Display, presentation audio, wireless mics | H13: 900 | I13: PLACEHOLDER | K13: =IF(L13="","",L13&"|"&COUNTIF($L$6:L13,L13)) | L13: Cocktail Hour Sound | M13: Speeches and toasts mic
D14: =IF(E14="","",E14&"|"&COUNTIF($E$6:E14,E14)) | E14: Room Rental | F14: Crew | G14: On-site technician for the event | H14: 600 | I14: PLACEHOLDER | K14: =IF(L14="","",L14&"|"&COUNTIF($L$6:L14,L14)) | L14: Cocktail Hour Sound | M14: All cabling and stands
D15: =IF(E15="","",E15&"|"&COUNTIF($E$6:E15,E15)) | K15: =IF(L15="","",L15&"|"&COUNTIF($L$6:L15,L15)) | L15: Room Rental | M15: Tables and chairs
D16: =IF(E16="","",E16&"|"&COUNTIF($E$6:E16,E16)) | K16: =IF(L16="","",L16&"|"&COUNTIF($L$6:L16,L16)) | L16: Room Rental | M16: Wi-Fi
D17: =IF(E17="","",E17&"|"&COUNTIF($E$6:E17,E17)) | K17: =IF(L17="","",L17&"|"&COUNTIF($L$6:L17,L17)) | L17: Room Rental | M17: Setup and breakdown
D18: =IF(E18="","",E18&"|"&COUNTIF($E$6:E18,E18)) | K18: =IF(L18="","",L18&"|"&COUNTIF($L$6:L18,L18))
D19: =IF(E19="","",E19&"|"&COUNTIF($E$6:E19,E19)) | K19: =IF(L19="","",L19&"|"&COUNTIF($L$6:L19,L19))
D20: =IF(E20="","",E20&"|"&COUNTIF($E$6:E20,E20)) | K20: =IF(L20="","",L20&"|"&COUNTIF($L$6:L20,L20))
D21: =IF(E21="","",E21&"|"&COUNTIF($E$6:E21,E21)) | K21: =IF(L21="","",L21&"|"&COUNTIF($L$6:L21,L21))
D22: =IF(E22="","",E22&"|"&COUNTIF($E$6:E22,E22)) | K22: =IF(L22="","",L22&"|"&COUNTIF($L$6:L22,L22))
D23: =IF(E23="","",E23&"|"&COUNTIF($E$6:E23,E23)) | K23: =IF(L23="","",L23&"|"&COUNTIF($L$6:L23,L23))
D24: =IF(E24="","",E24&"|"&COUNTIF($E$6:E24,E24)) | K24: =IF(L24="","",L24&"|"&COUNTIF($L$6:L24,L24))
D25: =IF(E25="","",E25&"|"&COUNTIF($E$6:E25,E25)) | K25: =IF(L25="","",L25&"|"&COUNTIF($L$6:L25,L25))
D26: =IF(E26="","",E26&"|"&COUNTIF($E$6:E26,E26)) | K26: =IF(L26="","",L26&"|"&COUNTIF($L$6:L26,L26))
D27: =IF(E27="","",E27&"|"&COUNTIF($E$6:E27,E27)) | K27: =IF(L27="","",L27&"|"&COUNTIF($L$6:L27,L27))
D28: =IF(E28="","",E28&"|"&COUNTIF($E$6:E28,E28)) | K28: =IF(L28="","",L28&"|"&COUNTIF($L$6:L28,L28))
D29: =IF(E29="","",E29&"|"&COUNTIF($E$6:E29,E29)) | K29: =IF(L29="","",L29&"|"&COUNTIF($L$6:L29,L29))
... D105: =IF(E105="","",E105&"|"&COUNTIF($E$6:E105,E105)) | K105: =IF(L105="","",L105&"|"&COUNTIF($L$6:L105,L105))
K106: =IF(L106="","",L106&"|"&COUNTIF($L$6:L106,L106))
K107: =IF(L107="","",L107&"|"&COUNTIF($L$6:L107,L107))
K108: =IF(L108="","",L108&"|"&COUNTIF($L$6:L108,L108))
K109: =IF(L109="","",L109&"|"&COUNTIF($L$6:L109,L109))
K110: =IF(L110="","",L110&"|"&COUNTIF($L$6:L110,L110))
K111: =IF(L111="","",L111&"|"&COUNTIF($L$6:L111,L111))
K112: =IF(L112="","",L112&"|"&COUNTIF($L$6:L112,L112))
K113: =IF(L113="","",L113&"|"&COUNTIF($L$6:L113,L113))
K114: =IF(L114="","",L114&"|"&COUNTIF($L$6:L114,L114))
K115: =IF(L115="","",L115&"|"&COUNTIF($L$6:L115,L115))
K116: =IF(L116="","",L116&"|"&COUNTIF($L$6:L116,L116))
...
